<?xml version="1.0"?>
<robot name="GS_arm"  xmlns:xacro= "http://www.ros.org/wiki/xacro">
<link name="part_1">
<visual>
<origin xyz="-0.048515588972450084115 -0.048381809756492616392 0.02168296178540153954" rpy="-2.9631100051819361241 -1.5407888913564720124 1.394061644504385411" />
<geometry>
<mesh filename="file://$(find arm_description_pkg)/meshes_upright_xacro_copy/part_1.stl"/>
</geometry>
<material name="part_1_material">
<color rgba="0.61568627450980395466 0.81176470588235294379 0.92941176470588238168 1.0"/>
</material>
</visual>
<collision>
<origin xyz="-0.048515588972450084115 -0.048381809756492616392 0.02168296178540153954" rpy="-2.9631100051819361241 -1.5407888913564720124 1.394061644504385411" />
<geometry>
<mesh filename="file://$(find arm_description_pkg)/meshes_upright_xacro_copy/part_1.stl"/>
</geometry>
</collision>
<inertial>
<origin xyz="3.9346208319395505624e-05 0.00029446104136088974146 0.0099838982703420505599" rpy="0 0 0"/>
<mass value="0.006609902445612011665" />
<inertia ixx="3.8557583804827948081e-07" ixy="-8.5817534015904601137e-12"  ixz="-2.9042567180569949555e-10" iyy="3.8552932008494348831e-07" iyz="-1.6261410778727158207e-09" izz="3.3054513047939213485e-07" />
</inertial>
</link>

<link name="part_2">
<visual>
<origin xyz="0.048859453325366328236 0.0029950000000000006999 0.056093852816584924281" rpy="5.9703311341315333088e-19 1.5764960949569704537e-18 3.7613820976254023211e-17" />
<geometry>
<mesh filename="file://$(find arm_description_pkg)/meshes_upright_xacro_copy/part_2.stl"/>
</geometry>
<material name="part_2_material">
<color rgba="0.64705882352941179736 0.64705882352941179736 0.64705882352941179736 1.0"/>
</material>
</visual>
<collision>
<origin xyz="0.048859453325366328236 0.0029950000000000006999 0.056093852816584924281" rpy="5.9703311341315333088e-19 1.5764960949569704537e-18 3.7613820976254023211e-17" />
<geometry>
<mesh filename="file://$(find arm_description_pkg)/meshes_upright_xacro_copy/part_2.stl"/>
</geometry>
</collision>
<inertial>
<origin xyz="6.9388939039072283776e-18 -1.5152666575259525593e-18 -0.0065746336890046414014" rpy="0 0 0"/>
<mass value="0.0004808546686908171967" />
<inertia ixx="9.2139062926419775468e-09" ixy="8.139769267325316743e-25"  ixz="-2.475053310557146353e-26" iyy="9.2892630950525905595e-09" iyz="-9.6407175983812253654e-27" izz="2.9508757354261818293e-09" />
</inertial>
</link>

<link name="arm_l2">
<visual>
<origin xyz="0.048859453325366328236 0.068093852816584921062 -3.4694469519536141888e-18" rpy="-1.570796326794896558 3.3082727961137533839e-18 4.2836429294882487265e-19" />
<geometry>
<mesh filename="file://$(find arm_description_pkg)/meshes_upright_xacro_copy/part_3.stl"/>
</geometry>
<material name="part_3_material">
<color rgba="0.2313725490196078538 0.38039215686274507888 0.7058823529411765163 1.0"/>
</material>
</visual>
<collision>
<origin xyz="0.048859453325366328236 0.068093852816584921062 -3.4694469519536141888e-18" rpy="-1.570796326794896558 3.3082727961137533839e-18 4.2836429294882487265e-19" />
<geometry>
<mesh filename="file://$(find arm_description_pkg)/meshes_upright_xacro_copy/part_3.stl"/>
</geometry>
</collision>
<visual>
<origin xyz="-0.048859453325366009047 0.068093852816583894105 0.0059999999999950995311" rpy="1.5707963267949300867 2.7769185012432494825e-14 -3.141592653589793116" />
<geometry>
<mesh filename="file://$(find arm_description_pkg)/meshes_upright_xacro_copy/part_3.stl"/>
</geometry>
<material name="part_3_material">
<color rgba="0.2313725490196078538 0.38039215686274507888 0.7058823529411765163 1.0"/>
</material>
</visual>
<collision>
<origin xyz="-0.048859453325366009047 0.068093852816583894105 0.0059999999999950995311" rpy="1.5707963267949300867 2.7769185012432494825e-14 -3.141592653589793116" />
<geometry>
<mesh filename="file://$(find arm_description_pkg)/meshes_upright_xacro_copy/part_3.stl"/>
</geometry>
</collision>
<inertial>
<origin xyz="4.1633363423443376429e-17 -0.019037059230557373812 0.0029999999999997029911" rpy="0 0 0"/>
<mass value="0.0018024175020168503505" />
<inertia ixx="2.9794982793760358521e-07" ixy="1.8117547509144998231e-23"  ixz="3.2375407516953010569e-21" iyy="4.5324558525216651031e-08" iyz="6.3828532344534446717e-22" izz="2.6757285137812776185e-07" />
</inertial>
</link>

<link name="part_4">
<visual>
<origin xyz="0.048859453325366328236 0.10580344317460763093 -0.0059999999999999949207" rpy="-1.570796326794896558 -2.568528757234289214e-17 1.2507229254702876666e-18" />
<geometry>
<mesh filename="file://$(find arm_description_pkg)/meshes_upright_xacro_copy/part_4.stl"/>
</geometry>
<material name="part_4_material">
<color rgba="0.91764705882352937127 0.91764705882352937127 0.91764705882352937127 1.0"/>
</material>
</visual>
<collision>
<origin xyz="0.048859453325366328236 0.10580344317460763093 -0.0059999999999999949207" rpy="-1.570796326794896558 -2.568528757234289214e-17 1.2507229254702876666e-18" />
<geometry>
<mesh filename="file://$(find arm_description_pkg)/meshes_upright_xacro_copy/part_4.stl"/>
</geometry>
</collision>
<inertial>
<origin xyz="0 -0.0057117447165234286333 -0.0029999999999999970267" rpy="0 0 0"/>
<mass value="0.00053403825361218694098" />
<inertia ixx="1.1631143592865942267e-08" ixy="2.1320178314783077322e-26"  ixz="4.9462198393585779837e-25" iyy="3.2279759003646011438e-09" iyz="-5.2880007843154898869e-26" izz="1.1672971935553085324e-08" />
</inertial>
</link>

<link name="part_5">
<visual>
<origin xyz="0.048859453325366342114 0.0029999999999999922562 0.11963971922331254061" rpy="-3.0312156515106290407e-18 6.8914379180104880284e-19 -4.9678747396574866895e-17" />
<geometry>
<mesh filename="file://$(find arm_description_pkg)/meshes_upright_xacro_copy/part_5.stl"/>
</geometry>
<material name="part_5_material">
<color rgba="0.76862745098039220171 0.88627450980392152857 0.95294117647058818044 1.0"/>
</material>
</visual>
<collision>
<origin xyz="0.048859453325366342114 0.0029999999999999922562 0.11963971922331254061" rpy="-3.0312156515106290407e-18 6.8914379180104880284e-19 -4.9678747396574866895e-17" />
<geometry>
<mesh filename="file://$(find arm_description_pkg)/meshes_upright_xacro_copy/part_5.stl"/>
</geometry>
</collision>
<inertial>
<origin xyz="0 -3.3929427308380349322e-18 -0.0096862342282897362367" rpy="0 0 0"/>
<mass value="0.00050620968453226309908" />
<inertia ixx="1.7292747018592618189e-08" ixy="-8.6796005849316754599e-25"  ixz="-1.206723927453641478e-26" iyy="1.7257442487639338247e-08" iyz="-5.6478357420234858492e-26" izz="2.1445115498377023545e-09" />
</inertial>
</link>

<link name="arm_endvec">
<visual>
<origin xyz="-0.032241423967342787427 0.057870514689952690102 0.0069999999999999749922" rpy="1.570796326794896336 -5.5172007175998599701e-17 -3.141592653589793116" />
<geometry>
<mesh filename="file://$(find arm_description_pkg)/meshes_upright_xacro_copy/part_6.stl"/>
</geometry>
<material name="part_6_material">
<color rgba="0.98039215686274505668 0.71372549019607844922 0.0039215686274509803377 1.0"/>
</material>
</visual>
<collision>
<origin xyz="-0.032241423967342787427 0.057870514689952690102 0.0069999999999999749922" rpy="1.570796326794896336 -5.5172007175998599701e-17 -3.141592653589793116" />
<geometry>
<mesh filename="file://$(find arm_description_pkg)/meshes_upright_xacro_copy/part_6.stl"/>
</geometry>
</collision>
<visual>
<origin xyz="0.032241423967343751933 0.05787051468995382808 -0.0020000000000000048121" rpy="-1.570796326794896558 3.3952139299299347159e-17 5.4986082872749708198e-18" />
<geometry>
<mesh filename="file://$(find arm_description_pkg)/meshes_upright_xacro_copy/part_6.stl"/>
</geometry>
<material name="part_6_material">
<color rgba="0.98039215686274505668 0.71372549019607844922 0.0039215686274509803377 1.0"/>
</material>
</visual>
<collision>
<origin xyz="0.032241423967343751933 0.05787051468995382808 -0.0020000000000000048121" rpy="-1.570796326794896558 3.3952139299299347159e-17 5.4986082872749708198e-18" />
<geometry>
<mesh filename="file://$(find arm_description_pkg)/meshes_upright_xacro_copy/part_6.stl"/>
</geometry>
</collision>
<inertial>
<origin xyz="-1.7347234759768070944e-17 0.0029802180805466350899 0.0024999999999999814038" rpy="0 0 0"/>
<mass value="0.00015286331097685208779" />
<inertia ixx="3.0189687538729663167e-09" ixy="1.5141618334763924121e-25"  ixz="9.0778278923035211859e-25" iyy="2.1145547742151836235e-09" iyz="5.6183052323074966867e-24" izz="1.2794076991921689214e-09" />
</inertial>
</link>

<link name="part_7">
<visual>
<origin xyz="0.032241423967343751933 -0.057870514689953855836 0.0019999999999999948375" rpy="1.570796326794896558 6.7151894296738239311e-17 7.3947303116085813605e-18" />
<geometry>
<mesh filename="file://$(find arm_description_pkg)/meshes_upright_xacro_copy/part_7.stl"/>
</geometry>
<material name="part_7_material">
<color rgba="0.61568627450980395466 0.81176470588235294379 0.92941176470588238168 1.0"/>
</material>
</visual>
<collision>
<origin xyz="0.032241423967343751933 -0.057870514689953855836 0.0019999999999999948375" rpy="1.570796326794896558 6.7151894296738239311e-17 7.3947303116085813605e-18" />
<geometry>
<mesh filename="file://$(find arm_description_pkg)/meshes_upright_xacro_copy/part_7.stl"/>
</geometry>
</collision>
<inertial>
<origin xyz="-0.0018778763456197276101 0.0038224345067999700339 -0.0021912702980041551433" rpy="0 0 0"/>
<mass value="0.00014229331727145028337" />
<inertia ixx="1.619226822912006319e-09" ixy="2.8910785378469890916e-10"  ixz="-7.892923260474739189e-11" iyy="5.4384221362638614807e-10" iyz="1.6430296018185187728e-10" izz="1.5973053132818108863e-09" />
</inertial>
</link>

<joint name="joint61" type="revolute">
<origin xyz="-1.0462550964485117788e-17 0.0060000000000000192069 -3.0357660829594124152e-18" rpy="-3.1415926535897851224 -8.6108532759730813131e-15 3.139847324337798895" />
<parent link="arm_endvec" />
<child link="part_7" />
<axis xyz="0 0 1"/>
<limit effort="1" velocity="20" lower="0.0017453292519943295908" upper="0.785398163397448279"/>
<joint_properties friction="0.0"/>
</joint>

<link name="part_7_2">
<visual>
<origin xyz="0.032241423967343751933 -0.05787051468995382808 0.0020000000000000017764" rpy="1.570796326794896558 -3.2146409090018830403e-18 1.8441980093554966676e-18" />
<geometry>
<mesh filename="file://$(find arm_description_pkg)/meshes_upright_xacro_copy/part_7.stl"/>
</geometry>
<material name="part_7_material">
<color rgba="0.61568627450980395466 0.81176470588235294379 0.92941176470588238168 1.0"/>
</material>
</visual>
<collision>
<origin xyz="0.032241423967343751933 -0.05787051468995382808 0.0020000000000000017764" rpy="1.570796326794896558 -3.2146409090018830403e-18 1.8441980093554966676e-18" />
<geometry>
<mesh filename="file://$(find arm_description_pkg)/meshes_upright_xacro_copy/part_7.stl"/>
</geometry>
</collision>
<inertial>
<origin xyz="-0.0018778763456197211049 0.0038224345067999973558 -0.0021912702980041503728" rpy="0 0 0"/>
<mass value="0.00014229331727145028337" />
<inertia ixx="1.6192268229120059054e-09" ixy="2.8910785378469880576e-10"  ixz="-7.8929232604747185095e-11" iyy="5.4384221362638614807e-10" iyz="1.6430296018185190313e-10" izz="1.5973053132818108863e-09" />
</inertial>
</link>

<joint name="joint62" type="revolute">
<origin xyz="-2.8080836267374564841e-17 0.005999999999999880429 0.0049999999999999749506" rpy="-2.4591996825169363138e-15 3.723392664202142389e-15 0.0017453292519943037868" />
<parent link="arm_endvec" />
<child link="part_7_2" />
<axis xyz="0 0 1"/>
<limit effort="1" velocity="20" lower="0.0017453292519943295908" upper="0.785398163397448279"/>
<joint_properties friction="0.0"/>
</joint>

<link name="part_8">
<visual>
<origin xyz="0.032241423967343758872 0.053156491136578713774 -2.6020852139652106416e-18" rpy="-1.570796326794896558 1.4213900380178171502e-17 1.794624716202049848e-19" />
<geometry>
<mesh filename="file://$(find arm_description_pkg)/meshes_upright_xacro_copy/part_8.stl"/>
</geometry>
<material name="part_8_material">
<color rgba="0.64705882352941179736 0.64705882352941179736 0.64705882352941179736 1.0"/>
</material>
</visual>
<collision>
<origin xyz="0.032241423967343758872 0.053156491136578713774 -2.6020852139652106416e-18" rpy="-1.570796326794896558 1.4213900380178171502e-17 1.794624716202049848e-19" />
<geometry>
<mesh filename="file://$(find arm_description_pkg)/meshes_upright_xacro_copy/part_8.stl"/>
</geometry>
</collision>
<inertial>
<origin xyz="-6.9388939039072283776e-18 -6.8787559343204407458e-05 -0.001400000000000002371" rpy="0 0 0"/>
<mass value="4.1683231231072220173e-05" />
<inertia ixx="7.2333447456293211371e-11" ixy="-5.5986418893166599128e-28"  ixz="-1.3910746246086449193e-26" iyy="8.0388087304381288815e-11" iyz="2.4810139852935701241e-28" izz="9.9693918154647561433e-11" />
</inertial>
</link>

<joint name="camJoint" type="fixed">
<origin xyz="-5.0957502106818708398e-18 0.0030000000000000165423 -0.0020000000000000004753" rpy="-1.957252694083210223e-15 8.6221801800839255138e-17 -3.141592653589793116" />
<parent link="arm_endvec" />
<child link="part_8" />
<axis xyz="0 0 1"/>
<limit effort="1" velocity="20" />
<joint_properties friction="0.0"/>
</joint>

<link name ="cam_link_oriented">
</link>

<joint name="camJoint_oriented" type="fixed">
    <origin xyz="0 -0.001 -0.001" rpy="3.1415 0 -1.57"/>
    <parent link="part_8" />
    <child link="cam_link_oriented" />
</joint>


<joint name="joint5" type="revolute">
<origin xyz="0.0025000000000000004857 -1.2042267411114387921e-17 -0.018025706946078176585" rpy="-1.570796326794896558 0.0029250332346841597525 1.5707963267948972241" />
<parent link="part_5" />
<child link="arm_endvec" />
<axis xyz="0 0 1"/>
<limit effort="1" velocity="20" lower="-0.785398163397448279" upper="0.785398163397448279"/>
<joint_properties friction="0.0"/>
</joint>

<joint name="joint4" type="revolute">
<origin xyz="-2.3744027577432547105e-17 -0.013836276048704937436 -0.0029999999999999948583" rpy="1.570796326794896558 7.9423360664544827361e-13 -3.1415926535897886751" />
<parent link="part_4" />
<child link="part_5" />
<axis xyz="0 0 1"/>
<limit effort="1" velocity="20" lower="-6.283185307179586232" upper="6.283185307179586232"/>
<joint_properties friction="0.0"/>
</joint>

<joint name="joint3" type="revolute">
<origin xyz="1.0033952293174441817e-17 -0.037709590358022709866 2.6020852139652106416e-18" rpy="3.1415926535897771288 -2.752648323891600667e-14 -3.1362970286540980958" />
<parent link="arm_l2" />
<child link="part_4" />
<axis xyz="0 0 1"/>
<limit effort="1" velocity="20" lower="-1.7453292519943295336" upper="1.7453292519943295336"/>
<joint_properties friction="0.0"/>
</joint>

<joint name="joint2" type="revolute">
<origin xyz="6.89484819065000476e-18 0.0029950000000000011335 -0.012000000000000010658" rpy="1.570796326794896558 -2.1133530940768447459e-15 -3.1840252851980965534e-14" />
<parent link="part_2" />
<child link="arm_l2" />
<axis xyz="0 0 1"/>
<limit effort="1" velocity="20" lower="-2.0943951023931952626" upper="2.0943951023931952626"/>
<joint_properties friction="0.0"/>
</joint>

<joint name="joint1" type="revolute">
<origin xyz="9.2096118081065603267e-05 0.00058981645737652549366 0.019979384169771963187" rpy="3.1157378617112496677 -0.015232452947603327895 -0.70902660590734545298" />
<parent link="part_1" />
<child link="part_2" />
<axis xyz="0 0 1"/>
<limit effort="1" velocity="20" lower="-3.141592653589793116" upper="3.141592653589793116"/>
<joint_properties friction="0.0"/>
</joint>

<link name="world"/>

<joint name="joint0" type="fixed">
<parent link="world"/>
<child link="part_1"/>
</joint>


</robot>