<robot name="GS_arm">
<link name="part_1">
<visual>
<origin xyz="-0.038971312419282880257 -0.0059074425007916604724 -0.05799673536979961519" rpy="-7.1325047143189308573e-10 2.5692278157425837292e-09 -1.5707963260270139116" />
<geometry>
<mesh filename="file://$(find arm_description_pkg)/meshes/part_1.stl"/>
</geometry>
<material name="part_1_material">
<color rgba="0.61568627450980395466 0.81176470588235294379 0.92941176470588238168 1.0"/>
</material>
</visual>
<collision>
<origin xyz="-0.038971312419282880257 -0.0059074425007916604724 -0.05799673536979961519" rpy="-7.1325047143189308573e-10 2.5692278157425837292e-09 -1.5707963260270139116" />
<geometry>
<mesh filename="file://$(find arm_description_pkg)/meshes/part_1.stl"/>
</geometry>
</collision>
<inertial>
<origin xyz="0.0097264373137582807449 0.0050069631188778091976 -0.0090849926749358989042" rpy="0 0 0"/>
<mass value="0.006573023007839362726" />
<inertia ixx="3.4254629420184499666e-07" ixy="2.4707195489864942007e-17"  ixz="-6.1231940596269248676e-25" iyy="3.1037055368538273128e-07" iyz="-8.2666807714617599638e-17" izz="3.4254629420184499666e-07" />
</inertial>
</link>

<link name="part_2">
<visual>
<origin xyz="0.048859453325366335175 0.0030000000000000009298 0.056093852816584924281" rpy="5.2939967216496537646e-27 7.0260817068364442039e-26 -4.2202792986425131631e-26" />
<geometry>
<mesh filename="file://$(find arm_description_pkg)/meshes/part_2.stl"/>
</geometry>
<material name="part_2_material">
<color rgba="0.64705882352941179736 0.64705882352941179736 0.64705882352941179736 1.0"/>
</material>
</visual>
<collision>
<origin xyz="0.048859453325366335175 0.0030000000000000009298 0.056093852816584924281" rpy="5.2939967216496537646e-27 7.0260817068364442039e-26 -4.2202792986425131631e-26" />
<geometry>
<mesh filename="file://$(find arm_description_pkg)/meshes/part_2.stl"/>
</geometry>
</collision>
<inertial>
<origin xyz="6.215245193508245336e-10 -4.3368086262239500843e-19 -0.0062870999215605821719" rpy="0 0 0"/>
<mass value="0.00039216508755759201931" />
<inertia ixx="6.4285143472704544266e-09" ixy="-2.8053211617079956656e-15"  ixz="-2.0325159501443300711e-15" iyy="6.5484390549443102828e-09" iyz="-8.7123341685784700129e-35" izz="1.7628285759493892712e-09" />
</inertial>
</link>

<link name="arm_l2">
<visual>
<origin xyz="-0.048859453325366467014 0.068093852816586336596 0.0059999999999997503247" rpy="1.5707963267949034414 -9.7144514674857918702e-15 3.141592653589793116" />
<geometry>
<mesh filename="file://$(find arm_description_pkg)/meshes/part_3.stl"/>
</geometry>
<material name="part_3_material">
<color rgba="0.2313725490196078538 0.38039215686274507888 0.7058823529411765163 1.0"/>
</material>
</visual>
<collision>
<origin xyz="-0.048859453325366467014 0.068093852816586336596 0.0059999999999997503247" rpy="1.5707963267949034414 -9.7144514674857918702e-15 3.141592653589793116" />
<geometry>
<mesh filename="file://$(find arm_description_pkg)/meshes/part_3.stl"/>
</geometry>
</collision>
<visual>
<origin xyz="0.048859453325366328236 0.068093852816584921062 0" rpy="-1.570796326794896558 -7.2829913884279140146e-27 5.2832357482394874954e-17" />
<geometry>
<mesh filename="file://$(find arm_description_pkg)/meshes/part_3.stl"/>
</geometry>
<material name="part_3_material">
<color rgba="0.2313725490196078538 0.38039215686274507888 0.7058823529411765163 1.0"/>
</material>
</visual>
<collision>
<origin xyz="0.048859453325366328236 0.068093852816584921062 0" rpy="-1.570796326794896558 -7.2829913884279140146e-27 5.2832357482394874954e-17" />
<geometry>
<mesh filename="file://$(find arm_description_pkg)/meshes/part_3.stl"/>
</geometry>
</collision>
<inertial>
<origin xyz="7.6327832942460490982e-17 -0.019072619004296215151 0.0029999999999999315409" rpy="0 0 0"/>
<mass value="0.0015763467425403791811" />
<inertia ixx="2.4386725160661472183e-07" ixy="2.4901284308402326939e-23"  ixz="-1.4213516827392348934e-15" iyy="3.5047571511437430924e-08" iyz="-8.6402892390285082958e-22" izz="2.1899899793860181808e-07" />
</inertial>
</link>

<link name="part_4">
<visual>
<origin xyz="0.048859453325366342114 -0.10580344317460763093 -3.5999999999999574007e-05" rpy="1.570796326794896558 -1.0772117594941155003e-25 -4.6914379226342727305e-18" />
<geometry>
<mesh filename="file://$(find arm_description_pkg)/meshes/part_4.stl"/>
</geometry>
<material name="part_4_material">
<color rgba="0.91764705882352937127 0.91764705882352937127 0.91764705882352937127 1.0"/>
</material>
</visual>
<collision>
<origin xyz="0.048859453325366342114 -0.10580344317460763093 -3.5999999999999574007e-05" rpy="1.570796326794896558 -1.0772117594941155003e-25 -4.6914379226342727305e-18" />
<geometry>
<mesh filename="file://$(find arm_description_pkg)/meshes/part_4.stl"/>
</geometry>
</collision>
<inertial>
<origin xyz="-2.5964344563256242341e-10 0.0059506274539454784289 -0.0030359999999999996365" rpy="0 0 0"/>
<mass value="0.0004391145489879284651" />
<inertia ixx="8.4064181992739358642e-09" ixy="2.0311123927716528783e-15"  ixz="6.6104554151935554773e-16" iyy="1.9494250132639217898e-09" iyz="-3.956802695660583404e-33" izz="8.5087706342363404576e-09" />
</inertial>
</link>

<link name="part_5">
<visual>
<origin xyz="0.048859453325366335175 0.0029999999999999991951 0.11963971922331255449" rpy="3.6777585056142152379e-18 -4.6527595579517413716e-17 -5.9186525231026205526e-18" />
<geometry>
<mesh filename="file://$(find arm_description_pkg)/meshes/part_5.stl"/>
</geometry>
<material name="part_5_material">
<color rgba="0.76862745098039220171 0.88627450980392152857 0.95294117647058818044 1.0"/>
</material>
</visual>
<collision>
<origin xyz="0.048859453325366335175 0.0029999999999999991951 0.11963971922331255449" rpy="3.6777585056142152379e-18 -4.6527595579517413716e-17 -5.9186525231026205526e-18" />
<geometry>
<mesh filename="file://$(find arm_description_pkg)/meshes/part_5.stl"/>
</geometry>
</collision>
<inertial>
<origin xyz="6.9388939039072283776e-18 2.5366670413638716652e-09 -0.0092615459733133148612" rpy="0 0 0"/>
<mass value="0.00041383713507877446184" />
<inertia ixx="1.2335222904467039203e-08" ixy="-6.799502945966000754e-26"  ixz="6.1850297472030453251e-25" iyy="1.2304438438045864217e-08" iyz="7.6863903660287903679e-15" izz="1.2824085971445473879e-09" />
</inertial>
</link>

<link name="arm_endvec">
<visual>
<origin xyz="0.032241423967343751933 0.057870514689953848897 -0.0010000000000000008882" rpy="-1.570796326794896558 9.6593088173496922144e-18 8.4176373614197601358e-18" />
<geometry>
<mesh filename="file://$(find arm_description_pkg)/meshes/part_8.stl"/>
</geometry>
<material name="part_8_material">
<color rgba="0.98039215686274505668 0.71372549019607844922 0.0039215686274509803377 1.0"/>
</material>
</visual>
<collision>
<origin xyz="0.032241423967343751933 0.057870514689953848897 -0.0010000000000000008882" rpy="-1.570796326794896558 9.6593088173496922144e-18 8.4176373614197601358e-18" />
<geometry>
<mesh filename="file://$(find arm_description_pkg)/meshes/part_8.stl"/>
</geometry>
</collision>
<visual>
<origin xyz="0.03224142396734377275 -0.052963864548872585658 0.0060000000000001926792" rpy="1.57079632679489678 -1.2230733206368237654e-17 1.7267348417151081348e-17" />
<geometry>
<mesh filename="file://$(find arm_description_pkg)/meshes/part_10.stl"/>
</geometry>
<material name="part_10_material">
<color rgba="0.64705882352941179736 0.64705882352941179736 0.64705882352941179736 1.0"/>
</material>
</visual>
<collision>
<origin xyz="0.03224142396734377275 -0.052963864548872585658 0.0060000000000001926792" rpy="1.57079632679489678 -1.2230733206368237654e-17 1.7267348417151081348e-17" />
<geometry>
<mesh filename="file://$(find arm_description_pkg)/meshes/part_10.stl"/>
</geometry>
</collision>
<visual>
<origin xyz="-0.03224142396734464705 0.057870514689955625254 0.005999999999999942879" rpy="1.5707963267949009989 4.0682459268865843569e-18 -3.141592653589793116" />
<geometry>
<mesh filename="file://$(find arm_description_pkg)/meshes/part_8.stl"/>
</geometry>
<material name="part_8_material">
<color rgba="0.98039215686274505668 0.71372549019607844922 0.0039215686274509803377 1.0"/>
</material>
</visual>
<collision>
<origin xyz="-0.03224142396734464705 0.057870514689955625254 0.005999999999999942879" rpy="1.5707963267949009989 4.0682459268865843569e-18 -3.141592653589793116" />
<geometry>
<mesh filename="file://$(find arm_description_pkg)/meshes/part_8.stl"/>
</geometry>
</collision>
<inertial>
<origin xyz="-1.8300575243750840785e-17 0.0015842633600372541675 0.0048273811403184846425" rpy="0 0 0"/>
<mass value="8.5366875729040575787e-05" />
<inertia ixx="1.144597230681657233e-09" ixy="-5.2792863965825358042e-25"  ixz="2.8787412206682346376e-24" iyy="9.9255823822816832336e-10" iyz="9.1302598556565177326e-11" izz="3.0166740426774707239e-10" />
</inertial>
</link>

<link name="part_9">
<visual>
<origin xyz="0.032241423967343765811 -0.057870514689953855836 0.0010000000000000078271" rpy="1.570796326794896558 -2.780614794904396428e-17 3.2084063177657466013e-18" />
<geometry>
<mesh filename="file://$(find arm_description_pkg)/meshes/part_9.stl"/>
</geometry>
<material name="part_9_material">
<color rgba="0.61568627450980395466 0.81176470588235294379 0.92941176470588238168 1.0"/>
</material>
</visual>
<collision>
<origin xyz="0.032241423967343765811 -0.057870514689953855836 0.0010000000000000078271" rpy="1.570796326794896558 -2.780614794904396428e-17 3.2084063177657466013e-18" />
<geometry>
<mesh filename="file://$(find arm_description_pkg)/meshes/part_9.stl"/>
</geometry>
</collision>
<inertial>
<origin xyz="-0.0018277785025753306991 0.0036316546605268326675 -0.0021681834033945453742" rpy="0 0 0"/>
<mass value="0.00014326580067568385349" />
<inertia ixx="1.5551384458104457859e-09" ixy="3.1638969266166242688e-10"  ixz="-8.43454635886494438e-11" iyy="5.1125140077094566832e-10" iyz="1.7003605750121371037e-10" izz="1.5818254057325908649e-09" />
</inertial>
</link>

<joint name="joint6_1" type="revolute">
<origin xyz="-1.4094628242311557642e-17 0.0039999999999999966138 0.0050000000000001501577" rpy="3.6989317647796961104e-16 9.6544237760437687954e-16 -1.5188841050849092327e-15" />
<parent link="arm_endvec" />
<child link="part_9" />
<axis xyz="0 0 1"/>
<limit effort="1" velocity="20" lower="0" upper="1.570796326794896558"/>
<joint_properties friction="0.0"/>
</joint>

<link name="part_9_2">
<visual>
<origin xyz="0.032241423967343751933 -0.057870514689953841958 0.00099999999999999394928" rpy="1.570796326794896558 2.3913450878113692354e-17 7.4659306411398371592e-18" />
<geometry>
<mesh filename="file://$(find arm_description_pkg)/meshes/part_9.stl"/>
</geometry>
<material name="part_9_material">
<color rgba="0.61568627450980395466 0.81176470588235294379 0.92941176470588238168 1.0"/>
</material>
</visual>
<collision>
<origin xyz="0.032241423967343751933 -0.057870514689953841958 0.00099999999999999394928" rpy="1.570796326794896558 2.3913450878113692354e-17 7.4659306411398371592e-18" />
<geometry>
<mesh filename="file://$(find arm_description_pkg)/meshes/part_9.stl"/>
</geometry>
</collision>
<inertial>
<origin xyz="-0.001827778502575337638 0.0036316546605268465453 -0.0021681834033945553489" rpy="0 0 0"/>
<mass value="0.00014326580067568385349" />
<inertia ixx="1.5551384458104449587e-09" ixy="3.1638969266166237518e-10"  ixz="-8.4345463588649585971e-11" iyy="5.1125140077094566832e-10" iyz="1.7003605750121391717e-10" izz="1.5818254057325908649e-09" />
</inertial>
</link>

<joint name="joint6_2" type="revolute">
<origin xyz="9.9746599868666407929e-18 0.0040000000000002568223 -6.2450045135165055399e-17" rpy="-3.1415926535897922278 4.0603929202504693162e-16 -3.141592653589793116" />
<parent link="arm_endvec" />
<child link="part_9_2" />
<axis xyz="0 0 1"/>
<limit effort="1" velocity="20" lower="0" upper="1.570796326794896558"/>
<joint_properties friction="0.0"/>
</joint>

<joint name="joint5" type="revolute">
<origin xyz="-0.0025299999999999975286 -7.1557343384043292644e-18 -0.018025706946078200871" rpy="-1.570796326794896558 -2.2428881371736324527e-15 -1.5707963267948970021" />
<parent link="part_5" />
<child link="arm_endvec" />
<axis xyz="0 0 1"/>
<limit effort="1" velocity="20" lower="-1.570796326794896558" upper="1.570796326794896558"/>
<joint_properties friction="0.0"/>
</joint>

<joint name="joint4" type="revolute">
<origin xyz="1.3877787807814456755e-17 0.013836276048704899272 -0.0030359999999999987691" rpy="1.570796326794896558 0.18509475809465084084 -4.863413034647360364e-15" />
<parent link="part_4" />
<child link="part_5" />
<axis xyz="0 0 1"/>
<limit effort="1" velocity="20" lower="-6.283185307179586232" upper="6.283185307179586232"/>
<joint_properties friction="0.0"/>
</joint>

<joint name="joint3" type="revolute">
<origin xyz="-1.3877787807814456755e-17 -0.037709590358022709866 0" rpy="3.141592653589793116 1.6718184578836537737e-16 -1.3962634015955452949" />
<parent link="arm_l2" />
<child link="part_4" />
<axis xyz="0 0 1"/>
<limit effort="1" velocity="20" lower="-3.141592653589793116" upper="3.141592653589793116"/>
<joint_properties friction="0.0"/>
</joint>

<joint name="joint2" type="revolute">
<origin xyz="1.0408340855860842566e-17 -0.0030359999999999996365 -0.01199999999999999678" rpy="1.570796326794896558 0.87266462599708660708 -3.1415926535897908956" />
<parent link="part_2" />
<child link="arm_l2" />
<axis xyz="0 0 1"/>
<limit effort="1" velocity="20" lower="-2.0943951023931952626" upper="2.0943951023931952626"/>
<joint_properties friction="0.0"/>
</joint>

<joint name="joint1" type="revolute">
<origin xyz="0.0097264373221392624175 -0.0059074425890629084224 -0.0090849927029775026655" rpy="-1.5707963260270139116 -1.5707963241285034517 0" />
<parent link="part_1" />
<child link="part_2" />
<axis xyz="0 0 1"/>
<limit effort="1" velocity="20" lower="-3.141592653589793116" upper="3.141592653589793116"/>
<joint_properties friction="0.0"/>
</joint>


</robot>
