<robot name="GS_arm">
<link name="part_1">
<visual>
<origin xyz="-0.04910700336525827131 -0.048580010032195260206 0.019651492183297165212" rpy="-1.5707963260270139116 -1.5707963241285023415 0" />
<geometry>
<mesh filename="file://$(find arm_description_pkg)/meshes/part_1.stl"/>
</geometry>
<material name="part_1_material">
<color rgba="0.61568627450980395466 0.81176470588235294379 0.92941176470588238168 1.0"/>
</material>
</visual>
<collision>
<origin xyz="-0.04910700336525827131 -0.048580010032195260206 0.019651492183297165212" rpy="-1.5707963260270139116 -1.5707963241285023415 0" />
<geometry>
<mesh filename="file://$(find arm_description_pkg)/meshes/part_1.stl"/>
</geometry>
</collision>
<inertial>
<origin xyz="-0.00040925370406562458806 0.00033173273479635001504 0.0087370865662881585373" rpy="0 0 0"/>
<mass value="0.006573023007839362726" />
<inertia ixx="3.4254629420184510254e-07" ixy="-6.1683605638088372916e-25"  ixz="-2.2949361586760868395e-17" iyy="3.4254629420184542017e-07" iyz="8.2666808706789062164e-17" izz="3.1037055368538326067e-07" />
</inertial>
</link>

<link name="part_2">
<visual>
<origin xyz="0.048859453325366328236 0.0029999999999999996288 0.056093852816584924281" rpy="4.0399032718099006475e-26 -5.2816658575524032903e-25 -7.8323145736917558873e-26" />
<geometry>
<mesh filename="file://$(find arm_description_pkg)/meshes/part_2.stl"/>
</geometry>
<material name="part_2_material">
<color rgba="0.64705882352941179736 0.64705882352941179736 0.64705882352941179736 1.0"/>
</material>
</visual>
<collision>
<origin xyz="0.048859453325366328236 0.0029999999999999996288 0.056093852816584924281" rpy="4.0399032718099006475e-26 -5.2816658575524032903e-25 -7.8323145736917558873e-26" />
<geometry>
<mesh filename="file://$(find arm_description_pkg)/meshes/part_2.stl"/>
</geometry>
</collision>
<inertial>
<origin xyz="6.215245124119305263e-10 -1.7347234696298535404e-18 -0.0062870999215605821719" rpy="0 0 0"/>
<mass value="0.00039216508755759201931" />
<inertia ixx="6.4285143472704544266e-09" ixy="-2.8053211617079956656e-15"  ixz="-2.0325159501443300711e-15" iyy="6.5484390549443102828e-09" iyz="1.9333278714826055754e-34" izz="1.7628285759493892712e-09" />
</inertial>
</link>

<link name="arm_l2">
<visual>
<origin xyz="-0.048859453325366480891 0.068093852816586336596 0.0059999999999997511921" rpy="1.5707963267949034414 -9.7144514674857918702e-15 3.141592653589793116" />
<geometry>
<mesh filename="file://$(find arm_description_pkg)/meshes/part_3.stl"/>
</geometry>
<material name="part_3_material">
<color rgba="0.2313725490196078538 0.38039215686274507888 0.7058823529411765163 1.0"/>
</material>
</visual>
<collision>
<origin xyz="-0.048859453325366480891 0.068093852816586336596 0.0059999999999997511921" rpy="1.5707963267949034414 -9.7144514674857918702e-15 3.141592653589793116" />
<geometry>
<mesh filename="file://$(find arm_description_pkg)/meshes/part_3.stl"/>
</geometry>
</collision>
<visual>
<origin xyz="0.048859453325366328236 0.068093852816584934939 0" rpy="-1.570796326794896558 -7.2829913884279140146e-27 5.2832357482394874954e-17" />
<geometry>
<mesh filename="file://$(find arm_description_pkg)/meshes/part_3.stl"/>
</geometry>
<material name="part_3_material">
<color rgba="0.2313725490196078538 0.38039215686274507888 0.7058823529411765163 1.0"/>
</material>
</visual>
<collision>
<origin xyz="0.048859453325366328236 0.068093852816584934939 0" rpy="-1.570796326794896558 -7.2829913884279140146e-27 5.2832357482394874954e-17" />
<geometry>
<mesh filename="file://$(find arm_description_pkg)/meshes/part_3.stl"/>
</geometry>
</collision>
<inertial>
<origin xyz="6.9388939037872537273e-17 -0.019072619004296208212 0.0029999999999999319746" rpy="0 0 0"/>
<mass value="0.0015763467425403791811" />
<inertia ixx="2.4386725160661461595e-07" ixy="2.4901284308402326939e-23"  ixz="-1.4213516358953332778e-15" iyy="3.5047571511437437541e-08" iyz="-8.1715750997435778484e-22" izz="2.1899899793860176514e-07" />
</inertial>
</link>

<link name="part_4">
<visual>
<origin xyz="0.048859453325366314358 -0.10580344317460763093 -3.5999999999999140327e-05" rpy="1.570796326794896558 -1.0772117594941155003e-25 -4.6914379226342727305e-18" />
<geometry>
<mesh filename="file://$(find arm_description_pkg)/meshes/part_4.stl"/>
</geometry>
<material name="part_4_material">
<color rgba="0.91764705882352937127 0.91764705882352937127 0.91764705882352937127 1.0"/>
</material>
</visual>
<collision>
<origin xyz="0.048859453325366314358 -0.10580344317460763093 -3.5999999999999140327e-05" rpy="1.570796326794896558 -1.0772117594941155003e-25 -4.6914379226342727305e-18" />
<geometry>
<mesh filename="file://$(find arm_description_pkg)/meshes/part_4.stl"/>
</geometry>
</collision>
<inertial>
<origin xyz="-2.5964347338813809074e-10 0.0059506274539454784289 -0.0030359999999999992028" rpy="0 0 0"/>
<mass value="0.0004391145489879284651" />
<inertia ixx="8.4064181992739358642e-09" ixy="2.0311123927716528783e-15"  ixz="6.6104554151935554773e-16" iyy="1.9494250132639217898e-09" iyz="-3.956802695660583404e-33" izz="8.5087706342363404576e-09" />
</inertial>
</link>

<link name="part_5">
<visual>
<origin xyz="0.048859453325366335175 0.0029999999999999974604 0.11963971922331256836" rpy="3.6777585056142152379e-18 -4.6527595579517413716e-17 -5.9186525231026205526e-18" />
<geometry>
<mesh filename="file://$(find arm_description_pkg)/meshes/part_5.stl"/>
</geometry>
<material name="part_5_material">
<color rgba="0.76862745098039220171 0.88627450980392152857 0.95294117647058818044 1.0"/>
</material>
</visual>
<collision>
<origin xyz="0.048859453325366335175 0.0029999999999999974604 0.11963971922331256836" rpy="3.6777585056142152379e-18 -4.6527595579517413716e-17 -5.9186525231026205526e-18" />
<geometry>
<mesh filename="file://$(find arm_description_pkg)/meshes/part_5.stl"/>
</geometry>
</collision>
<inertial>
<origin xyz="6.9388939039072283776e-18 2.5366670396291490164e-09 -0.0092615459733133027181" rpy="0 0 0"/>
<mass value="0.00041383713507877446184" />
<inertia ixx="1.2335222904467039203e-08" ixy="-6.799502945966000754e-26"  ixz="6.1850297472030453251e-25" iyy="1.2304438438045864217e-08" iyz="7.6863903660287903679e-15" izz="1.2824085971445473879e-09" />
</inertial>
</link>

<link name="arm_endvec">
<visual>
<origin xyz="0.032241423967343758872 0.057870514689953841958 -0.00099999999999999394928" rpy="-1.570796326794896558 9.6593088173496922144e-18 8.4176373614197601358e-18" />
<geometry>
<mesh filename="file://$(find arm_description_pkg)/meshes/part_8.stl"/>
</geometry>
<material name="part_8_material">
<color rgba="0.98039215686274505668 0.71372549019607844922 0.0039215686274509803377 1.0"/>
</material>
</visual>
<collision>
<origin xyz="0.032241423967343758872 0.057870514689953841958 -0.00099999999999999394928" rpy="-1.570796326794896558 9.6593088173496922144e-18 8.4176373614197601358e-18" />
<geometry>
<mesh filename="file://$(find arm_description_pkg)/meshes/part_8.stl"/>
</geometry>
</collision>
<visual>
<origin xyz="0.032241423967343779688 -0.052963864548872585658 0.0060000000000001926792" rpy="1.57079632679489678 -1.2230733206368237654e-17 1.7267348417151081348e-17" />
<geometry>
<mesh filename="file://$(find arm_description_pkg)/meshes/part_10.stl"/>
</geometry>
<material name="part_10_material">
<color rgba="0.64705882352941179736 0.64705882352941179736 0.64705882352941179736 1.0"/>
</material>
</visual>
<collision>
<origin xyz="0.032241423967343779688 -0.052963864548872585658 0.0060000000000001926792" rpy="1.57079632679489678 -1.2230733206368237654e-17 1.7267348417151081348e-17" />
<geometry>
<mesh filename="file://$(find arm_description_pkg)/meshes/part_10.stl"/>
</geometry>
</collision>
<visual>
<origin xyz="-0.032241423967344640111 0.057870514689955618315 0.0059999999999999498179" rpy="1.5707963267949009989 4.0682459268865843569e-18 -3.141592653589793116" />
<geometry>
<mesh filename="file://$(find arm_description_pkg)/meshes/part_8.stl"/>
</geometry>
<material name="part_8_material">
<color rgba="0.98039215686274505668 0.71372549019607844922 0.0039215686274509803377 1.0"/>
</material>
</visual>
<collision>
<origin xyz="-0.032241423967344640111 0.057870514689955618315 0.0059999999999999498179" rpy="1.5707963267949009989 4.0682459268865843569e-18 -3.141592653589793116" />
<geometry>
<mesh filename="file://$(find arm_description_pkg)/meshes/part_8.stl"/>
</geometry>
</collision>
<inertial>
<origin xyz="-1.1361681339843615489e-17 0.0015842633600372474454 0.0048273811403184881119" rpy="0 0 0"/>
<mass value="8.5366875729040575787e-05" />
<inertia ixx="1.1445972306816553719e-09" ixy="-5.2792863965823356029e-25"  ixz="1.9706467671457961893e-24" iyy="9.925582382281668758e-10" iyz="9.1302598556563587588e-11" izz="3.0166740426774660711e-10" />
</inertial>
</link>

<link name="part_9">
<visual>
<origin xyz="0.032241423967343765811 -0.05787051468995382808 0.00099999999999999394928" rpy="1.570796326794896558 -2.780614794904396428e-17 3.2084063177657466013e-18" />
<geometry>
<mesh filename="file://$(find arm_description_pkg)/meshes/part_9.stl"/>
</geometry>
<material name="part_9_material">
<color rgba="0.61568627450980395466 0.81176470588235294379 0.92941176470588238168 1.0"/>
</material>
</visual>
<collision>
<origin xyz="0.032241423967343765811 -0.05787051468995382808 0.00099999999999999394928" rpy="1.570796326794896558 -2.780614794904396428e-17 3.2084063177657466013e-18" />
<geometry>
<mesh filename="file://$(find arm_description_pkg)/meshes/part_9.stl"/>
</geometry>
</collision>
<inertial>
<origin xyz="-0.001827778502575337638 0.0036316546605268747346 -0.0021681834033945596857" rpy="0 0 0"/>
<mass value="0.00014326580067568379928" />
<inertia ixx="1.5551384458104457859e-09" ixy="3.1638969266166242688e-10"  ixz="-8.4345463588649456724e-11" iyy="5.1125140077094546152e-10" iyz="1.7003605750121371037e-10" izz="1.5818254057325908649e-09" />
</inertial>
</link>

<joint name="joint6_1" type="revolute">
<origin xyz="8.6736173798840354721e-18 0.0039999999999999896749 0.0050000000000001501577" rpy="3.6989317647796961104e-16 9.6544237760437687954e-16 -1.5188841050849092327e-15" />
<parent link="arm_endvec" />
<child link="part_9" />
<axis xyz="0 0 1"/>
<limit effort="1" velocity="20" lower="0" upper="1.570796326794896558"/>
<joint_properties friction="0.0"/>
</joint>

<link name="part_9_2">
<visual>
<origin xyz="0.032241423967343751933 -0.057870514689953848897 0.00099999999999999394928" rpy="1.570796326794896558 2.3913450878113692354e-17 7.4659306411398371592e-18" />
<geometry>
<mesh filename="file://$(find arm_description_pkg)/meshes/part_9.stl"/>
</geometry>
<material name="part_9_material">
<color rgba="0.61568627450980395466 0.81176470588235294379 0.92941176470588238168 1.0"/>
</material>
</visual>
<collision>
<origin xyz="0.032241423967343751933 -0.057870514689953848897 0.00099999999999999394928" rpy="1.570796326794896558 2.3913450878113692354e-17 7.4659306411398371592e-18" />
<geometry>
<mesh filename="file://$(find arm_description_pkg)/meshes/part_9.stl"/>
</geometry>
</collision>
<inertial>
<origin xyz="-0.0018277785025753445769 0.0036316546605268530505 -0.0021681834033945557826" rpy="0 0 0"/>
<mass value="0.00014326580067568379928" />
<inertia ixx="1.5551384458104449587e-09" ixy="3.1638969266166237518e-10"  ixz="-8.4345463588649598896e-11" iyy="5.1125140077094546152e-10" iyz="1.7003605750121391717e-10" izz="1.5818254057325908649e-09" />
</inertial>
</link>

<joint name="joint6_2" type="revolute">
<origin xyz="-1.7347234759768070944e-18 0.0040000000000000035527 -6.9388939039072283776e-18" rpy="-3.1415926535897922278 4.0603929202504693162e-16 -3.141592653589793116" />
<parent link="arm_endvec" />
<child link="part_9_2" />
<axis xyz="0 0 1"/>
<limit effort="1" velocity="20" lower="0" upper="1.570796326794896558"/>
<joint_properties friction="0.0"/>
</joint>

<joint name="joint5" type="revolute">
<origin xyz="-0.0025300000000000183453 -1.7347234759768070944e-18 -0.018025706946078190462" rpy="-1.570796326794896558 -2.2428881371736324527e-15 -1.5707963267948970021" />
<parent link="part_5" />
<child link="arm_endvec" />
<axis xyz="0 0 1"/>
<limit effort="1" velocity="20" lower="-1.570796326794896558" upper="1.570796326794896558"/>
<joint_properties friction="0.0"/>
</joint>

<joint name="joint4" type="revolute">
<origin xyz="-1.3877787807814456755e-17 0.013836276048704923558 -0.0030360000000000000701" rpy="1.570796326794896558 0.18509475809465084084 -4.863413034647360364e-15" />
<parent link="part_4" />
<child link="part_5" />
<axis xyz="0 0 1"/>
<limit effort="1" velocity="20" lower="-6.283185307179586232" upper="6.283185307179586232"/>
<joint_properties friction="0.0"/>
</joint>

<joint name="joint3" type="revolute">
<origin xyz="0 -0.037709590358022723744 4.336808689942017736e-19" rpy="3.141592653589793116 1.6718184578836537737e-16 -1.3962634015955452949" />
<parent link="arm_l2" />
<child link="part_4" />
<axis xyz="0 0 1"/>
<limit effort="1" velocity="20" lower="-3.141592653589793116" upper="3.141592653589793116"/>
<joint_properties friction="0.0"/>
</joint>

<joint name="joint2" type="revolute">
<origin xyz="5.9089018400459991653e-18 -0.0030359999999999996365 -0.011999999999999989841" rpy="1.5707963267948978903 -0.69813170079781894373 -3.1415926535897904515" />
<parent link="part_2" />
<child link="arm_l2" />
<axis xyz="0 0 1"/>
<limit effort="1" velocity="20" lower="-2.0943951023931952626" upper="2.0943951023931952626"/>
<joint_properties friction="0.0"/>
</joint>

<joint name="joint1" type="revolute">
<origin xyz="-0.00040925369628092445745 0.0003317327067547462538 0.019651492274228882229" rpy="-3.1415926528765427683 -2.5692277957900096269e-09 1.5707963275627829791" />
<parent link="part_1" />
<child link="part_2" />
<axis xyz="0 0 1"/>
<limit effort="1" velocity="20" lower="-3.141592653589793116" upper="3.141592653589793116"/>
<joint_properties friction="0.0"/>
</joint>


</robot>
