<sdf version='1.7'>
  <world name='default'>
    <light name='sun' type='directional'>
      <cast_shadows>1</cast_shadows>
      <pose>0 0 10 0 -0 0</pose>
      <diffuse>0.8 0.8 0.8 1</diffuse>
      <specular>0.2 0.2 0.2 1</specular>
      <attenuation>
        <range>1000</range>
        <constant>0.9</constant>
        <linear>0.01</linear>
        <quadratic>0.001</quadratic>
      </attenuation>
      <direction>-0.5 0.1 -0.9</direction>
      <spot>
        <inner_angle>0</inner_angle>
        <outer_angle>0</outer_angle>
        <falloff>0</falloff>
      </spot>
    </light>
    <model name='ground_plane'>
      <static>1</static>
      <link name='link'>
        <collision name='collision'>
          <geometry>
            <plane>
              <normal>0 0 1</normal>
              <size>100 100</size>
            </plane>
          </geometry>
          <surface>
            <friction>
              <ode>
                <mu>100</mu>
                <mu2>50</mu2>
              </ode>
              <torsional>
                <ode/>
              </torsional>
            </friction>
            <contact>
              <ode/>
            </contact>
            <bounce/>
          </surface>
          <max_contacts>10</max_contacts>
        </collision>
        <visual name='visual'>
          <cast_shadows>0</cast_shadows>
          <geometry>
            <plane>
              <normal>0 0 1</normal>
              <size>100 100</size>
            </plane>
          </geometry>
          <material>
            <script>
              <uri>file://media/materials/scripts/gazebo.material</uri>
              <name>Gazebo/Grey</name>
            </script>
          </material>
        </visual>
        <self_collide>0</self_collide>
        <enable_wind>0</enable_wind>
        <kinematic>0</kinematic>
      </link>
    </model>
    <gravity>0 0 -9.8</gravity>
    <magnetic_field>6e-06 2.3e-05 -4.2e-05</magnetic_field>
    <atmosphere type='adiabatic'/>
    <physics type='ode'>
      <max_step_size>0.001</max_step_size>
      <real_time_factor>1</real_time_factor>
      <real_time_update_rate>1000</real_time_update_rate>
    </physics>
    <scene>
      <ambient>0.4 0.4 0.4 1</ambient>
      <background>0.7 0.7 0.7 1</background>
      <shadows>1</shadows>
    </scene>
    <audio>
      <device>default</device>
    </audio>
    <wind/>
    <spherical_coordinates>
      <surface_model>EARTH_WGS84</surface_model>
      <latitude_deg>0</latitude_deg>
      <longitude_deg>0</longitude_deg>
      <elevation>0</elevation>
      <heading_deg>0</heading_deg>
    </spherical_coordinates>
    <model name='GS_arm'>
      <joint name='joint_0' type='fixed'>
        <pose relative_to='__model__'>0 0 0 0 -0 0</pose>
        <parent>world</parent>
        <child>part_1</child>
      </joint>
      <link name='part_1'>
        <pose relative_to='joint_0'>0 0 0 0 -0 0</pose>
        <inertial>
          <pose>3.9e-05 0.000294 0.009984 0 -0 0</pose>
          <mass>0.0066099</mass>
          <inertia>
            <ixx>3.85576e-07</ixx>
            <ixy>-8.58175e-12</ixy>
            <ixz>-2.90426e-10</ixz>
            <iyy>3.85529e-07</iyy>
            <iyz>-1.62614e-09</iyz>
            <izz>3.30545e-07</izz>
          </inertia>
        </inertial>
        <collision name='part_1_collision'>
          <pose>-0.048516 -0.048382 0.021683 -2.96311 -1.54079 1.39406</pose>
          <geometry>
            <mesh>
              <scale>1 1 1</scale>
              <uri>file:///home/nobel/workspace_arm/IRoC_U_arm/arm_ws/install/arm_description_pkg/share/arm_description_pkg/meshes_upright_xacro_copy/part_1.stl</uri>
            </mesh>
          </geometry>
          <surface>
            <contact>
              <ode/>
            </contact>
            <friction>
              <ode/>
              <torsional>
                <ode/>
              </torsional>
            </friction>
            <bounce/>
          </surface>
          <max_contacts>10</max_contacts>
        </collision>
        <visual name='part_1_visual'>
          <pose>-0.048516 -0.048382 0.021683 -2.96311 -1.54079 1.39406</pose>
          <geometry>
            <mesh>
              <scale>1 1 1</scale>
              <uri>file:///home/nobel/workspace_arm/IRoC_U_arm/arm_ws/install/arm_description_pkg/share/arm_description_pkg/meshes_upright_xacro_copy/part_1.stl</uri>
            </mesh>
          </geometry>
          <material>
            <script>
              <name>Gazebo/Blue</name>
              <uri>file://media/materials/scripts/gazebo.material</uri>
            </script>
          </material>
        </visual>
        <self_collide>0</self_collide>
        <enable_wind>0</enable_wind>
        <kinematic>0</kinematic>
      </link>
      <joint name='joint1' type='revolute'>
        <pose relative_to='part_1'>9.2e-05 0.00059 0.019979 3.11574 -0.015232 -0.709027</pose>
        <parent>part_1</parent>
        <child>part_2</child>
        <axis>
          <xyz>0 0 1</xyz>
          <limit>
            <lower>-3.14159</lower>
            <upper>3.14159</upper>
            <effort>1</effort>
            <velocity>20</velocity>
          </limit>
          <dynamics>
            <spring_reference>0</spring_reference>
            <spring_stiffness>0</spring_stiffness>
          </dynamics>
        </axis>
      </joint>
      <link name='part_2'>
        <pose relative_to='joint1'>0 0 0 0 -0 0</pose>
        <inertial>
          <pose>0 -0 -0.006575 0 -0 0</pose>
          <mass>0.000480855</mass>
          <inertia>
            <ixx>9.21391e-09</ixx>
            <ixy>8.13977e-25</ixy>
            <ixz>-2.47505e-26</ixz>
            <iyy>9.28926e-09</iyy>
            <iyz>-9.64072e-27</iyz>
            <izz>2.95088e-09</izz>
          </inertia>
        </inertial>
        <collision name='part_2_collision'>
          <pose>0.048859 0.002995 0.056094 0 -0 0</pose>
          <geometry>
            <mesh>
              <scale>1 1 1</scale>
              <uri>file:///home/nobel/workspace_arm/IRoC_U_arm/arm_ws/install/arm_description_pkg/share/arm_description_pkg/meshes_upright_xacro_copy/part_2.stl</uri>
            </mesh>
          </geometry>
          <surface>
            <contact>
              <ode/>
            </contact>
            <friction>
              <ode/>
              <torsional>
                <ode/>
              </torsional>
            </friction>
            <bounce/>
          </surface>
          <max_contacts>10</max_contacts>
        </collision>
        <visual name='part_2_visual'>
          <pose>0.048859 0.002995 0.056094 0 -0 0</pose>
          <geometry>
            <mesh>
              <scale>1 1 1</scale>
              <uri>file:///home/nobel/workspace_arm/IRoC_U_arm/arm_ws/install/arm_description_pkg/share/arm_description_pkg/meshes_upright_xacro_copy/part_2.stl</uri>
            </mesh>
          </geometry>
          <material>
            <script>
              <name>Gazebo/Red</name>
              <uri>file://media/materials/scripts/gazebo.material</uri>
            </script>
          </material>
        </visual>
        <self_collide>0</self_collide>
        <enable_wind>0</enable_wind>
        <kinematic>0</kinematic>
      </link>
      <joint name='joint2' type='revolute'>
        <pose relative_to='part_2'>0 0.002995 -0.012 1.5708 -0 0</pose>
        <parent>part_2</parent>
        <child>arm_l2</child>
        <axis>
          <xyz>0 0 1</xyz>
          <limit>
            <lower>-2.0944</lower>
            <upper>2.0944</upper>
            <effort>1</effort>
            <velocity>20</velocity>
          </limit>
          <dynamics>
            <spring_reference>0</spring_reference>
            <spring_stiffness>0</spring_stiffness>
          </dynamics>
        </axis>
      </joint>
      <link name='arm_l2'>
        <pose relative_to='joint2'>0 0 0 0 -0 0</pose>
        <inertial>
          <pose>0 -0.019037 0.003 0 -0 0</pose>
          <mass>0.00180242</mass>
          <inertia>
            <ixx>2.9795e-07</ixx>
            <ixy>1.81175e-23</ixy>
            <ixz>3.23754e-21</ixz>
            <iyy>4.53246e-08</iyy>
            <iyz>6.38285e-22</iyz>
            <izz>2.67573e-07</izz>
          </inertia>
        </inertial>
        <collision name='arm_l2_collision'>
          <pose>0.048859 0.068094 -0 -1.5708 0 0</pose>
          <geometry>
            <mesh>
              <scale>1 1 1</scale>
              <uri>file:///home/nobel/workspace_arm/IRoC_U_arm/arm_ws/install/arm_description_pkg/share/arm_description_pkg/meshes_upright_xacro_copy/part_3.stl</uri>
            </mesh>
          </geometry>
          <surface>
            <contact>
              <ode/>
            </contact>
            <friction>
              <ode/>
              <torsional>
                <ode/>
              </torsional>
            </friction>
            <bounce/>
          </surface>
          <max_contacts>10</max_contacts>
        </collision>
        <collision name='arm_l2_collision_1'>
          <pose>-0.048859 0.068094 0.006 1.5708 -0 -3.14159</pose>
          <geometry>
            <mesh>
              <scale>1 1 1</scale>
              <uri>file:///home/nobel/workspace_arm/IRoC_U_arm/arm_ws/install/arm_description_pkg/share/arm_description_pkg/meshes_upright_xacro_copy/part_3.stl</uri>
            </mesh>
          </geometry>
          <surface>
            <contact>
              <ode/>
            </contact>
            <friction>
              <ode/>
              <torsional>
                <ode/>
              </torsional>
            </friction>
            <bounce/>
          </surface>
          <max_contacts>10</max_contacts>
        </collision>
        <visual name='arm_l2_visual'>
          <pose>0.048859 0.068094 -0 -1.5708 0 0</pose>
          <geometry>
            <mesh>
              <scale>1 1 1</scale>
              <uri>file:///home/nobel/workspace_arm/IRoC_U_arm/arm_ws/install/arm_description_pkg/share/arm_description_pkg/meshes_upright_xacro_copy/part_3.stl</uri>
            </mesh>
          </geometry>
          <material>
            <script>
              <name>Gazebo/Green</name>
              <uri>file://media/materials/scripts/gazebo.material</uri>
            </script>
          </material>
        </visual>
        <visual name='arm_l2_visual_1'>
          <pose>-0.048859 0.068094 0.006 1.5708 -0 -3.14159</pose>
          <geometry>
            <mesh>
              <scale>1 1 1</scale>
              <uri>file:///home/nobel/workspace_arm/IRoC_U_arm/arm_ws/install/arm_description_pkg/share/arm_description_pkg/meshes_upright_xacro_copy/part_3.stl</uri>
            </mesh>
          </geometry>
          <material>
            <script>
              <name>Gazebo/Green</name>
              <uri>file://media/materials/scripts/gazebo.material</uri>
            </script>
          </material>
        </visual>
        <self_collide>0</self_collide>
        <enable_wind>0</enable_wind>
        <kinematic>0</kinematic>
      </link>
      <joint name='joint3' type='revolute'>
        <pose relative_to='arm_l2'>0 -0.03771 0 3.14159 -0 -3.1363</pose>
        <parent>arm_l2</parent>
        <child>part_4</child>
        <axis>
          <xyz>0 0 1</xyz>
          <limit>
            <lower>-1.74533</lower>
            <upper>1.74533</upper>
            <effort>1</effort>
            <velocity>20</velocity>
          </limit>
          <dynamics>
            <spring_reference>0</spring_reference>
            <spring_stiffness>0</spring_stiffness>
          </dynamics>
        </axis>
      </joint>
      <link name='part_4'>
        <pose relative_to='joint3'>0 0 0 0 -0 0</pose>
        <inertial>
          <pose>-0 -0.005712 -0.003 0 -0 0</pose>
          <mass>0.000534038</mass>
          <inertia>
            <ixx>1.16311e-08</ixx>
            <ixy>2.13202e-26</ixy>
            <ixz>4.94622e-25</ixz>
            <iyy>3.22798e-09</iyy>
            <iyz>-5.288e-26</iyz>
            <izz>1.1673e-08</izz>
          </inertia>
        </inertial>
        <collision name='part_4_collision'>
          <pose>0.048859 0.105803 -0.006 -1.5708 -0 0</pose>
          <geometry>
            <mesh>
              <scale>1 1 1</scale>
              <uri>file:///home/nobel/workspace_arm/IRoC_U_arm/arm_ws/install/arm_description_pkg/share/arm_description_pkg/meshes_upright_xacro_copy/part_4.stl</uri>
            </mesh>
          </geometry>
          <surface>
            <contact>
              <ode/>
            </contact>
            <friction>
              <ode/>
              <torsional>
                <ode/>
              </torsional>
            </friction>
            <bounce/>
          </surface>
          <max_contacts>10</max_contacts>
        </collision>
        <visual name='part_4_visual'>
          <pose>0.048859 0.105803 -0.006 -1.5708 -0 0</pose>
          <geometry>
            <mesh>
              <scale>1 1 1</scale>
              <uri>file:///home/nobel/workspace_arm/IRoC_U_arm/arm_ws/install/arm_description_pkg/share/arm_description_pkg/meshes_upright_xacro_copy/part_4.stl</uri>
            </mesh>
          </geometry>
          <material>
            <script>
              <name>Gazebo/White</name>
              <uri>file://media/materials/scripts/gazebo.material</uri>
            </script>
          </material>
        </visual>
        <self_collide>0</self_collide>
        <enable_wind>0</enable_wind>
        <kinematic>0</kinematic>
      </link>
      <joint name='joint4' type='revolute'>
        <pose relative_to='part_4'>-0 -0.013836 -0.003 1.5708 -0 -3.14159</pose>
        <parent>part_4</parent>
        <child>part_5</child>
        <axis>
          <xyz>0 0 1</xyz>
          <limit>
            <lower>-6.28319</lower>
            <upper>6.28319</upper>
            <effort>1</effort>
            <velocity>20</velocity>
          </limit>
          <dynamics>
            <spring_reference>0</spring_reference>
            <spring_stiffness>0</spring_stiffness>
          </dynamics>
        </axis>
      </joint>
      <link name='part_5'>
        <pose relative_to='joint4'>0 0 0 0 -0 0</pose>
        <inertial>
          <pose>0 -0 -0.009686 0 -0 0</pose>
          <mass>0.00050621</mass>
          <inertia>
            <ixx>1.72927e-08</ixx>
            <ixy>-8.6796e-25</ixy>
            <ixz>-1.20672e-26</ixz>
            <iyy>1.72574e-08</iyy>
            <iyz>-5.64784e-26</iyz>
            <izz>2.14451e-09</izz>
          </inertia>
        </inertial>
        <collision name='part_5_collision'>
          <pose>0.048859 0.003 0.11964 0 -0 0</pose>
          <geometry>
            <mesh>
              <scale>1 1 1</scale>
              <uri>file:///home/nobel/workspace_arm/IRoC_U_arm/arm_ws/install/arm_description_pkg/share/arm_description_pkg/meshes_upright_xacro_copy/part_5.stl</uri>
            </mesh>
          </geometry>
          <surface>
            <contact>
              <ode/>
            </contact>
            <friction>
              <ode/>
              <torsional>
                <ode/>
              </torsional>
            </friction>
            <bounce/>
          </surface>
          <max_contacts>10</max_contacts>
        </collision>
        <visual name='part_5_visual'>
          <pose>0.048859 0.003 0.11964 0 -0 0</pose>
          <geometry>
            <mesh>
              <scale>1 1 1</scale>
              <uri>file:///home/nobel/workspace_arm/IRoC_U_arm/arm_ws/install/arm_description_pkg/share/arm_description_pkg/meshes_upright_xacro_copy/part_5.stl</uri>
            </mesh>
          </geometry>
          <material>
            <script>
              <name>Gazebo/Gray</name>
              <uri>file://media/materials/scripts/gazebo.material</uri>
            </script>
          </material>
        </visual>
        <self_collide>0</self_collide>
        <enable_wind>0</enable_wind>
        <kinematic>0</kinematic>
      </link>
      <joint name='joint5' type='revolute'>
        <pose relative_to='part_5'>0.0025 -0 -0.018026 -1.5708 0.002925 1.5708</pose>
        <parent>part_5</parent>
        <child>arm_endvec</child>
        <axis>
          <xyz>0 0 1</xyz>
          <limit>
            <lower>-0.785398</lower>
            <upper>0.785398</upper>
            <effort>1</effort>
            <velocity>20</velocity>
          </limit>
          <dynamics>
            <spring_reference>0</spring_reference>
            <spring_stiffness>0</spring_stiffness>
          </dynamics>
        </axis>
      </joint>
      <link name='arm_endvec'>
        <pose relative_to='joint5'>0 0 0 0 -0 0</pose>
        <inertial>
          <pose>-0 0.002846 0.001236 0 -0 0</pose>
          <mass>0.000194547</mass>
          <inertia>
            <ixx>4.24422e-09</ixx>
            <ixy>9.2226e-25</ixy>
            <ixz>6.25588e-24</ixz>
            <iyy>3.33505e-09</iyy>
            <iyz>-1.20862e-10</iyz>
            <izz>1.39191e-09</izz>
          </inertia>
        </inertial>
        <collision name='arm_endvec_collision'>
          <pose>-0.032241 0.057871 0.007 1.5708 -0 -3.14159</pose>
          <geometry>
            <mesh>
              <scale>1 1 1</scale>
              <uri>file:///home/nobel/workspace_arm/IRoC_U_arm/arm_ws/install/arm_description_pkg/share/arm_description_pkg/meshes_upright_xacro_copy/part_6.stl</uri>
            </mesh>
          </geometry>
          <surface>
            <contact>
              <ode/>
            </contact>
            <friction>
              <ode/>
              <torsional>
                <ode/>
              </torsional>
            </friction>
            <bounce/>
          </surface>
          <max_contacts>10</max_contacts>
        </collision>
        <collision name='arm_endvec_collision_1'>
          <pose>-0.032241 -0.050871 -0.002 -1.5708 -0 -3.14159</pose>
          <geometry>
            <mesh>
              <scale>1 1 1</scale>
              <uri>file:///home/nobel/workspace_arm/IRoC_U_arm/arm_ws/install/arm_description_pkg/share/arm_description_pkg/meshes_upright_xacro_copy/part_8.stl</uri>
            </mesh>
          </geometry>
          <surface>
            <contact>
              <ode/>
            </contact>
            <friction>
              <ode/>
              <torsional>
                <ode/>
              </torsional>
            </friction>
            <bounce/>
          </surface>
          <max_contacts>10</max_contacts>
        </collision>
        <collision name='arm_endvec_collision_2'>
          <pose>0.032241 0.057871 -0.002 -1.5708 0 0</pose>
          <geometry>
            <mesh>
              <scale>1 1 1</scale>
              <uri>file:///home/nobel/workspace_arm/IRoC_U_arm/arm_ws/install/arm_description_pkg/share/arm_description_pkg/meshes_upright_xacro_copy/part_6.stl</uri>
            </mesh>
          </geometry>
          <surface>
            <contact>
              <ode/>
            </contact>
            <friction>
              <ode/>
              <torsional>
                <ode/>
              </torsional>
            </friction>
            <bounce/>
          </surface>
          <max_contacts>10</max_contacts>
        </collision>
        <visual name='arm_endvec_visual'>
          <pose>-0.032241 0.057871 0.007 1.5708 -0 -3.14159</pose>
          <geometry>
            <mesh>
              <scale>1 1 1</scale>
              <uri>file:///home/nobel/workspace_arm/IRoC_U_arm/arm_ws/install/arm_description_pkg/share/arm_description_pkg/meshes_upright_xacro_copy/part_6.stl</uri>
            </mesh>
          </geometry>
          <material>
            <script>
              <name>Gazebo/Yellow</name>
              <uri>file://media/materials/scripts/gazebo.material</uri>
            </script>
          </material>
        </visual>
        <visual name='arm_endvec_visual_1'>
          <pose>-0.032241 -0.050871 -0.002 -1.5708 -0 -3.14159</pose>
          <geometry>
            <mesh>
              <scale>1 1 1</scale>
              <uri>file:///home/nobel/workspace_arm/IRoC_U_arm/arm_ws/install/arm_description_pkg/share/arm_description_pkg/meshes_upright_xacro_copy/part_8.stl</uri>
            </mesh>
          </geometry>
          <material>
            <script>
              <name>Gazebo/Yellow</name>
              <uri>file://media/materials/scripts/gazebo.material</uri>
            </script>
          </material>
        </visual>
        <visual name='arm_endvec_visual_2'>
          <pose>0.032241 0.057871 -0.002 -1.5708 0 0</pose>
          <geometry>
            <mesh>
              <scale>1 1 1</scale>
              <uri>file:///home/nobel/workspace_arm/IRoC_U_arm/arm_ws/install/arm_description_pkg/share/arm_description_pkg/meshes_upright_xacro_copy/part_6.stl</uri>
            </mesh>
          </geometry>
          <material>
            <script>
              <name>Gazebo/Yellow</name>
              <uri>file://media/materials/scripts/gazebo.material</uri>
            </script>
          </material>
        </visual>
        <self_collide>0</self_collide>
        <enable_wind>0</enable_wind>
        <kinematic>0</kinematic>
      </link>
      <joint name='joint61' type='revolute'>
        <pose relative_to='arm_endvec'>-0 0.006 -0 -3.14159 -0 3.13985</pose>
        <parent>arm_endvec</parent>
        <child>part_7</child>
        <axis>
          <xyz>0 0 1</xyz>
          <limit>
            <lower>0.00174533</lower>
            <upper>0.785398</upper>
            <effort>1</effort>
            <velocity>20</velocity>
          </limit>
          <dynamics>
            <spring_reference>0</spring_reference>
            <spring_stiffness>0</spring_stiffness>
          </dynamics>
        </axis>
      </joint>
      <link name='part_7'>
        <pose relative_to='joint61'>0 0 0 0 -0 0</pose>
        <inertial>
          <pose>-0.001878 0.003822 -0.002191 0 -0 0</pose>
          <mass>0.000142293</mass>
          <inertia>
            <ixx>1.61923e-09</ixx>
            <ixy>2.89108e-10</ixy>
            <ixz>-7.89292e-11</ixz>
            <iyy>5.43842e-10</iyy>
            <iyz>1.64303e-10</iyz>
            <izz>1.59731e-09</izz>
          </inertia>
        </inertial>
        <collision name='part_7_collision'>
          <pose>0.032241 -0.057871 0.002 1.5708 -0 0</pose>
          <geometry>
            <mesh>
              <scale>1 1 1</scale>
              <uri>file:///home/nobel/workspace_arm/IRoC_U_arm/arm_ws/install/arm_description_pkg/share/arm_description_pkg/meshes_upright_xacro_copy/part_7.stl</uri>
            </mesh>
          </geometry>
          <max_contacts>10</max_contacts>
          <surface>
            <contact>
              <ode/>
            </contact>
            <bounce/>
            <friction>
              <torsional>
                <ode/>
              </torsional>
              <ode/>
            </friction>
          </surface>
        </collision>
        <visual name='part_7_visual'>
          <pose>0.032241 -0.057871 0.002 1.5708 -0 0</pose>
          <geometry>
            <mesh>
              <scale>1 1 1</scale>
              <uri>file:///home/nobel/workspace_arm/IRoC_U_arm/arm_ws/install/arm_description_pkg/share/arm_description_pkg/meshes_upright_xacro_copy/part_7.stl</uri>
            </mesh>
          </geometry>
        </visual>
        <self_collide>0</self_collide>
        <enable_wind>0</enable_wind>
        <kinematic>0</kinematic>
      </link>
      <joint name='joint62' type='revolute'>
        <pose relative_to='arm_endvec'>-0 0.006 0.005 0 -0 0.001745</pose>
        <parent>arm_endvec</parent>
        <child>part_7_2</child>
        <axis>
          <xyz>0 0 1</xyz>
          <limit>
            <lower>0.00174533</lower>
            <upper>0.785398</upper>
            <effort>1</effort>
            <velocity>20</velocity>
          </limit>
          <dynamics>
            <spring_reference>0</spring_reference>
            <spring_stiffness>0</spring_stiffness>
          </dynamics>
        </axis>
      </joint>
      <link name='part_7_2'>
        <pose relative_to='joint62'>0 0 0 0 -0 0</pose>
        <inertial>
          <pose>-0.001878 0.003822 -0.002191 0 -0 0</pose>
          <mass>0.000142293</mass>
          <inertia>
            <ixx>1.61923e-09</ixx>
            <ixy>2.89108e-10</ixy>
            <ixz>-7.89292e-11</ixz>
            <iyy>5.43842e-10</iyy>
            <iyz>1.64303e-10</iyz>
            <izz>1.59731e-09</izz>
          </inertia>
        </inertial>
        <collision name='part_7_2_collision'>
          <pose>0.032241 -0.057871 0.002 1.5708 -0 0</pose>
          <geometry>
            <mesh>
              <scale>1 1 1</scale>
              <uri>file:///home/nobel/workspace_arm/IRoC_U_arm/arm_ws/install/arm_description_pkg/share/arm_description_pkg/meshes_upright_xacro_copy/part_7.stl</uri>
            </mesh>
          </geometry>
          <max_contacts>10</max_contacts>
          <surface>
            <contact>
              <ode/>
            </contact>
            <bounce/>
            <friction>
              <torsional>
                <ode/>
              </torsional>
              <ode/>
            </friction>
          </surface>
        </collision>
        <visual name='part_7_2_visual'>
          <pose>0.032241 -0.057871 0.002 1.5708 -0 0</pose>
          <geometry>
            <mesh>
              <scale>1 1 1</scale>
              <uri>file:///home/nobel/workspace_arm/IRoC_U_arm/arm_ws/install/arm_description_pkg/share/arm_description_pkg/meshes_upright_xacro_copy/part_7.stl</uri>
            </mesh>
          </geometry>
        </visual>
        <self_collide>0</self_collide>
        <enable_wind>0</enable_wind>
        <kinematic>0</kinematic>
      </link>
      <static>0</static>
      <plugin name='gazebo_ros2_control' filename='libgazebo_ros2_control.so'>
        <robot_param>robot_description</robot_param>
        <robot_param_node>robot_state_publisher</robot_param_node>
        <parameters>/home/nobel/workspace_arm/IRoC_U_arm/arm_ws/install/arm_controller_pkg/share/arm_controller_pkg/config/arm_controller_ros2.yaml</parameters>
      </plugin>
      <pose>0 0 0 0 -0 0</pose>
    </model>
    <state world_name='default'>
      <sim_time>95 267000000</sim_time>
      <real_time>95 478574985</real_time>
      <wall_time>1716393010 910903484</wall_time>
      <iterations>95267</iterations>
      <model name='GS_arm'>
        <pose>3.6e-05 7.2e-05 0.00016 0.014155 -0.005468 -0.000852</pose>
        <scale>1 1 1</scale>
        <link name='arm_endvec'>
          <pose>0.052833 0.036594 0.007184 -3.14128 0.442137 1.56984</pose>
          <velocity>0.00426 -0.004563 0.004702 0.627147 0.576646 0.042513</velocity>
          <acceleration>0.285554 -0.092595 8.87363 -1.66404 -0.727807 -0.823354</acceleration>
          <wrench>5.6e-05 -1.8e-05 0.001726 0 -0 0</wrench>
        </link>
        <link name='arm_l2'>
          <pose>-0.001624 0.002969 0.032112 1.55616 -1.04069 0.602648</pose>
          <velocity>0.005816 -0.002355 0.000421 0.094823 0.27317 -0.096297</velocity>
          <acceleration>-0.402417 -0.651271 -1.45897 -0.05859 -1.05694 -0.451274</acceleration>
          <wrench>-0.000725 -0.001174 -0.00263 0 -0 0</wrench>
        </link>
        <link name='part_1'>
          <pose>3.6e-05 7.2e-05 0.00016 0.014155 -0.005468 -0.000852</pose>
          <velocity>-9.6e-05 0.000854 -0.000337 0.083107 0.131668 -0.05878</velocity>
          <acceleration>-0.257354 0.113038 -0.013208 -2.3244 1.0863 0.029053</acceleration>
          <wrench>-0.001701 0.000747 -8.7e-05 0 -0 0</wrench>
        </link>
        <link name='part_2'>
          <pose>7.7e-05 0.000395 0.020149 -3.13483 0.001447 -2.54999</pose>
          <velocity>0.002455 -0.001343 -0.000346 0.059469 0.314101 -0.128694</velocity>
          <acceleration>0.237235 -0.020388 -0.049616 -0.012444 1.3797 1.04459</acceleration>
          <wrench>0.000114 -1e-05 -2.4e-05 0 -0 0</wrench>
        </link>
        <link name='part_4'>
          <pose>0.025494 0.02095 0.013044 1.60209 1.31195 -2.52121</pose>
          <velocity>0.002326 -0.003387 -0.005217 0.309888 -0.09828 -0.082709</velocity>
          <acceleration>-0.734522 -0.970396 -0.873935 1.44073 0.117625 0.037982</acceleration>
          <wrench>-0.000392 -0.000518 -0.000467 0 -0 0</wrench>
        </link>
        <link name='part_5'>
          <pose>0.038305 0.02587 0.009531 -0.931086 -1.12861 1.56565</pose>
          <velocity>0.003314 -0.003456 -0.002195 0.787305 0.22712 -0.266898</velocity>
          <acceleration>0.974161 -0.525797 5.1433 0.560573 -0.345322 0.161447</acceleration>
          <wrench>0.000493 -0.000266 0.002604 0 -0 0</wrench>
        </link>
        <link name='part_7'>
          <pose>0.05884 0.036596 0.00719 -0.186002 -0.405377 -1.12784</pose>
          <velocity>0.008634 0.001831 0.011066 -1.01565 0.680559 1.07819</velocity>
          <acceleration>1.05735 5.2478 14.0703 1.7507 0.840197 -0.833021</acceleration>
          <wrench>0.00015 0.000747 0.002002 0 -0 0</wrench>
        </link>
        <link name='part_7_2'>
          <pose>0.058831 0.034445 0.002661 3.13124 0.442142 1.5442</pose>
          <velocity>0.005924 -0.003842 0.001947 0.567797 0.510628 0.880462</velocity>
          <acceleration>5.02656 1.96868 7.09141 1.31587 -0.886755 -1.851</acceleration>
          <wrench>0.000715 0.00028 0.001009 0 -0 0</wrench>
        </link>
      </model>
      <model name='ground_plane'>
        <pose>0 0 0 0 -0 0</pose>
        <scale>1 1 1</scale>
        <link name='link'>
          <pose>0 0 0 0 -0 0</pose>
          <velocity>0 0 0 0 -0 0</velocity>
          <acceleration>0 0 0 0 -0 0</acceleration>
          <wrench>0 0 0 0 -0 0</wrench>
        </link>
      </model>
      <model name='unit_cylinder'>
        <pose>0.001199 0.109976 0.00749 3.14159 8e-05 8.8e-05</pose>
        <scale>1 1 1</scale>
        <link name='link'>
          <pose>0.001199 0.109976 0.00749 3.14159 8e-05 8.8e-05</pose>
          <velocity>0 0 0 0 -0 0</velocity>
          <acceleration>0 0 -9.8 0 -0 0</acceleration>
          <wrench>0 0 -1.96 0 -0 0</wrench>
        </link>
      </model>
      <model name='unit_cylinder_clone'>
        <pose>0.086413 0.000702 0.007491 3.14155 -0.000152 8.8e-05</pose>
        <scale>1 1 1</scale>
        <link name='link'>
          <pose>0.086413 0.000702 0.007491 3.14155 -0.000152 8.8e-05</pose>
          <velocity>0 0 0 0 -0 0</velocity>
          <acceleration>0 0 -9.8 0 -0 0</acceleration>
          <wrench>0 0 -1.96 0 -0 0</wrench>
        </link>
      </model>
      <model name='unit_cylinder_clone_0'>
        <pose>0.107288 0.370655 0.0075 3.14159 8.2e-05 8.8e-05</pose>
        <scale>1 1 1</scale>
        <link name='link'>
          <pose>0.107288 0.370655 0.0075 3.14159 8.2e-05 8.8e-05</pose>
          <velocity>0 0 0 0 -0 0</velocity>
          <acceleration>0 0 0 0 -0 0</acceleration>
          <wrench>0 0 0 0 -0 0</wrench>
        </link>
      </model>
      <model name='unit_cylinder_clone_1'>
        <pose>0.385205 0.136155 0.0075 3.14159 8.2e-05 8.8e-05</pose>
        <scale>1 1 1</scale>
        <link name='link'>
          <pose>0.385205 0.136155 0.0075 3.14159 8.2e-05 8.8e-05</pose>
          <velocity>0 0 0 0 -0 0</velocity>
          <acceleration>0 0 0 0 -0 0</acceleration>
          <wrench>0 0 0 0 -0 0</wrench>
        </link>
      </model>
      <model name='unit_cylinder_clone_clone'>
        <pose>0.195494 0.238627 0.007501 3.14154 -0.000155 8.8e-05</pose>
        <scale>1 1 1</scale>
        <link name='link'>
          <pose>0.195494 0.238627 0.007501 3.14154 -0.000155 8.8e-05</pose>
          <velocity>0 0 0 0 -0 0</velocity>
          <acceleration>0 0 0 0 -0 0</acceleration>
          <wrench>0 0 0 0 -0 0</wrench>
        </link>
      </model>
      <model name='unit_cylinder_clone_clone_clone'>
        <pose>-0.000535 1.2249 0.007501 3.14154 -0.000155 8.8e-05</pose>
        <scale>1 1 1</scale>
        <link name='link'>
          <pose>-0.000535 1.2249 0.007501 3.14154 -0.000155 8.8e-05</pose>
          <velocity>0 0 0 0 -0 0</velocity>
          <acceleration>0 0 0 0 -0 0</acceleration>
          <wrench>0 0 0 0 -0 0</wrench>
        </link>
      </model>
      <light name='sun'>
        <pose>0 0 10 0 -0 0</pose>
      </light>
    </state>
    <model name='unit_cylinder'>
      <link name='link'>
        <inertial>
          <mass>0.2</mass>
          <inertia>
            <ixx>0.0291667</ixx>
            <ixy>0</ixy>
            <ixz>0</ixz>
            <iyy>0.0291667</iyy>
            <iyz>0</iyz>
            <izz>0.025</izz>
          </inertia>
          <pose>0 0 0 0 -0 0</pose>
        </inertial>
        <self_collide>0</self_collide>
        <enable_wind>0</enable_wind>
        <kinematic>0</kinematic>
        <pose>0 -0 0 0 -0 0</pose>
        <gravity>1</gravity>
        <visual name='visual'>
          <geometry>
            <cylinder>
              <radius>0.004</radius>
              <length>0.015</length>
            </cylinder>
          </geometry>
          <material>
            <script>
              <name>Gazebo/Grey</name>
              <uri>file://media/materials/scripts/gazebo.material</uri>
            </script>
            <shader type='pixel'>
              <normal_map>__default__</normal_map>
            </shader>
            <ambient>1 0 0 1</ambient>
            <diffuse>1 0 0 1</diffuse>
            <specular>1 0 0 1</specular>
            <emissive>0 0 0 1</emissive>
          </material>
          <pose>0 0 0 0 -0 0</pose>
          <transparency>0</transparency>
          <cast_shadows>1</cast_shadows>
        </visual>
        <collision name='collision'>
          <laser_retro>0</laser_retro>
          <max_contacts>10</max_contacts>
          <pose>0 0 0 0 -0 0</pose>
          <geometry>
            <cylinder>
              <radius>0.004</radius>
              <length>0.015</length>
            </cylinder>
          </geometry>
          <surface>
            <friction>
              <ode>
                <mu>1</mu>
                <mu2>1</mu2>
                <fdir1>0 0 0</fdir1>
                <slip1>0</slip1>
                <slip2>0</slip2>
              </ode>
              <torsional>
                <coefficient>1</coefficient>
                <patch_radius>0</patch_radius>
                <surface_radius>0</surface_radius>
                <use_patch_radius>1</use_patch_radius>
                <ode>
                  <slip>0</slip>
                </ode>
              </torsional>
            </friction>
            <bounce>
              <restitution_coefficient>0</restitution_coefficient>
              <threshold>1e+06</threshold>
            </bounce>
            <contact>
              <collide_without_contact>0</collide_without_contact>
              <collide_without_contact_bitmask>1</collide_without_contact_bitmask>
              <collide_bitmask>1</collide_bitmask>
              <ode>
                <soft_cfm>0</soft_cfm>
                <soft_erp>0.2</soft_erp>
                <kp>1e+13</kp>
                <kd>1</kd>
                <max_vel>0.01</max_vel>
                <min_depth>0</min_depth>
              </ode>
              <bullet>
                <split_impulse>1</split_impulse>
                <split_impulse_penetration_threshold>-0.01</split_impulse_penetration_threshold>
                <soft_cfm>0</soft_cfm>
                <soft_erp>0.2</soft_erp>
                <kp>1e+13</kp>
                <kd>1</kd>
              </bullet>
            </contact>
          </surface>
        </collision>
      </link>
      <static>0</static>
      <allow_auto_disable>1</allow_auto_disable>
      <pose>0.097068 0.105495 0.0075 3.14159 1.3e-05 -0.472219</pose>
    </model>
    <model name='unit_cylinder_clone'>
      <link name='link'>
        <inertial>
          <mass>0.2</mass>
          <inertia>
            <ixx>0.0291667</ixx>
            <ixy>0</ixy>
            <ixz>0</ixz>
            <iyy>0.0291667</iyy>
            <iyz>0</iyz>
            <izz>0.025</izz>
          </inertia>
          <pose>0 0 0 0 -0 0</pose>
        </inertial>
        <self_collide>0</self_collide>
        <enable_wind>0</enable_wind>
        <kinematic>0</kinematic>
        <pose>0 0 0 0 -0 0</pose>
        <gravity>1</gravity>
        <visual name='visual'>
          <geometry>
            <cylinder>
              <radius>0.004</radius>
              <length>0.015</length>
            </cylinder>
          </geometry>
          <material>
            <script>
              <name>Gazebo/Grey</name>
              <uri>file://media/materials/scripts/gazebo.material</uri>
            </script>
            <shader type='pixel'>
              <normal_map>__default__</normal_map>
            </shader>
            <ambient>0 0 1 1</ambient>
            <diffuse>0 0 1 1</diffuse>
            <specular>0 0 0.9 1</specular>
            <emissive>0 0 0 1</emissive>
          </material>
          <pose>0 0 0 0 -0 0</pose>
          <transparency>0</transparency>
          <cast_shadows>1</cast_shadows>
        </visual>
        <collision name='collision'>
          <laser_retro>0</laser_retro>
          <max_contacts>10</max_contacts>
          <pose>0 0 0 0 -0 0</pose>
          <geometry>
            <cylinder>
              <radius>0.004</radius>
              <length>0.015</length>
            </cylinder>
          </geometry>
          <surface>
            <friction>
              <ode>
                <mu>1</mu>
                <mu2>1</mu2>
                <fdir1>0 0 0</fdir1>
                <slip1>0</slip1>
                <slip2>0</slip2>
              </ode>
              <torsional>
                <coefficient>1</coefficient>
                <patch_radius>0</patch_radius>
                <surface_radius>0</surface_radius>
                <use_patch_radius>1</use_patch_radius>
                <ode>
                  <slip>0</slip>
                </ode>
              </torsional>
            </friction>
            <bounce>
              <restitution_coefficient>0</restitution_coefficient>
              <threshold>1e+06</threshold>
            </bounce>
            <contact>
              <collide_without_contact>0</collide_without_contact>
              <collide_without_contact_bitmask>1</collide_without_contact_bitmask>
              <collide_bitmask>1</collide_bitmask>
              <ode>
                <soft_cfm>0</soft_cfm>
                <soft_erp>0.2</soft_erp>
                <kp>1e+13</kp>
                <kd>1</kd>
                <max_vel>0.01</max_vel>
                <min_depth>0</min_depth>
              </ode>
              <bullet>
                <split_impulse>1</split_impulse>
                <split_impulse_penetration_threshold>-0.01</split_impulse_penetration_threshold>
                <soft_cfm>0</soft_cfm>
                <soft_erp>0.2</soft_erp>
                <kp>1e+13</kp>
                <kd>1</kd>
              </bullet>
            </contact>
          </surface>
        </collision>
      </link>
      <static>0</static>
      <allow_auto_disable>1</allow_auto_disable>
      <pose>0.086414 0.000702 0.007501 -3.14159 1.3e-05 8.8e-05</pose>
    </model>
    <model name='unit_cylinder_clone_0'>
      <link name='link'>
        <inertial>
          <mass>0.2</mass>
          <inertia>
            <ixx>0.0291667</ixx>
            <ixy>0</ixy>
            <ixz>0</ixz>
            <iyy>0.0291667</iyy>
            <iyz>0</iyz>
            <izz>0.025</izz>
          </inertia>
          <pose>0 0 0 0 -0 0</pose>
        </inertial>
        <self_collide>0</self_collide>
        <enable_wind>0</enable_wind>
        <kinematic>0</kinematic>
        <pose>0 -0 0 0 -0 0</pose>
        <gravity>1</gravity>
        <visual name='visual'>
          <geometry>
            <cylinder>
              <radius>0.004</radius>
              <length>0.015</length>
            </cylinder>
          </geometry>
          <material>
            <script>
              <name>Gazebo/Grey</name>
              <uri>file://media/materials/scripts/gazebo.material</uri>
            </script>
            <shader type='pixel'>
              <normal_map>__default__</normal_map>
            </shader>
            <ambient>1 0 0 1</ambient>
            <diffuse>1 0 0 1</diffuse>
            <specular>1 0 0 1</specular>
            <emissive>0 0 0 1</emissive>
          </material>
          <pose>0 0 0 0 -0 0</pose>
          <transparency>0</transparency>
          <cast_shadows>1</cast_shadows>
        </visual>
        <collision name='collision'>
          <laser_retro>0</laser_retro>
          <max_contacts>10</max_contacts>
          <pose>0 0 0 0 -0 0</pose>
          <geometry>
            <cylinder>
              <radius>0.004</radius>
              <length>0.015</length>
            </cylinder>
          </geometry>
          <surface>
            <friction>
              <ode>
                <mu>1</mu>
                <mu2>1</mu2>
                <fdir1>0 0 0</fdir1>
                <slip1>0</slip1>
                <slip2>0</slip2>
              </ode>
              <torsional>
                <coefficient>1</coefficient>
                <patch_radius>0</patch_radius>
                <surface_radius>0</surface_radius>
                <use_patch_radius>1</use_patch_radius>
                <ode>
                  <slip>0</slip>
                </ode>
              </torsional>
            </friction>
            <bounce>
              <restitution_coefficient>0</restitution_coefficient>
              <threshold>1e+06</threshold>
            </bounce>
            <contact>
              <collide_without_contact>0</collide_without_contact>
              <collide_without_contact_bitmask>1</collide_without_contact_bitmask>
              <collide_bitmask>1</collide_bitmask>
              <ode>
                <soft_cfm>0</soft_cfm>
                <soft_erp>0.2</soft_erp>
                <kp>1e+13</kp>
                <kd>1</kd>
                <max_vel>0.01</max_vel>
                <min_depth>0</min_depth>
              </ode>
              <bullet>
                <split_impulse>1</split_impulse>
                <split_impulse_penetration_threshold>-0.01</split_impulse_penetration_threshold>
                <soft_cfm>0</soft_cfm>
                <soft_erp>0.2</soft_erp>
                <kp>1e+13</kp>
                <kd>1</kd>
              </bullet>
            </contact>
          </surface>
        </collision>
      </link>
      <static>0</static>
      <allow_auto_disable>1</allow_auto_disable>
      <pose>0.107288 0.370655 0.0075 3.14159 8.2e-05 8.8e-05</pose>
    </model>
    <model name='unit_cylinder_clone_clone'>
      <link name='link'>
        <inertial>
          <mass>0.2</mass>
          <inertia>
            <ixx>0.0291667</ixx>
            <ixy>0</ixy>
            <ixz>0</ixz>
            <iyy>0.0291667</iyy>
            <iyz>0</iyz>
            <izz>0.025</izz>
          </inertia>
          <pose>0 0 0 0 -0 0</pose>
        </inertial>
        <self_collide>0</self_collide>
        <enable_wind>0</enable_wind>
        <kinematic>0</kinematic>
        <pose>0 0 0 0 -0 0</pose>
        <gravity>1</gravity>
        <visual name='visual'>
          <geometry>
            <cylinder>
              <radius>0.004</radius>
              <length>0.015</length>
            </cylinder>
          </geometry>
          <material>
            <script>
              <name>Gazebo/Grey</name>
              <uri>file://media/materials/scripts/gazebo.material</uri>
            </script>
            <shader type='pixel'>
              <normal_map>__default__</normal_map>
            </shader>
            <ambient>0 0 1 1</ambient>
            <diffuse>0 0 1 1</diffuse>
            <specular>0 0 0.9 1</specular>
            <emissive>0 0 0 1</emissive>
          </material>
          <pose>0 0 0 0 -0 0</pose>
          <transparency>0</transparency>
          <cast_shadows>1</cast_shadows>
        </visual>
        <collision name='collision'>
          <laser_retro>0</laser_retro>
          <max_contacts>10</max_contacts>
          <pose>0 0 0 0 -0 0</pose>
          <geometry>
            <cylinder>
              <radius>0.004</radius>
              <length>0.015</length>
            </cylinder>
          </geometry>
          <surface>
            <friction>
              <ode>
                <mu>1</mu>
                <mu2>1</mu2>
                <fdir1>0 0 0</fdir1>
                <slip1>0</slip1>
                <slip2>0</slip2>
              </ode>
              <torsional>
                <coefficient>1</coefficient>
                <patch_radius>0</patch_radius>
                <surface_radius>0</surface_radius>
                <use_patch_radius>1</use_patch_radius>
                <ode>
                  <slip>0</slip>
                </ode>
              </torsional>
            </friction>
            <bounce>
              <restitution_coefficient>0</restitution_coefficient>
              <threshold>1e+06</threshold>
            </bounce>
            <contact>
              <collide_without_contact>0</collide_without_contact>
              <collide_without_contact_bitmask>1</collide_without_contact_bitmask>
              <collide_bitmask>1</collide_bitmask>
              <ode>
                <soft_cfm>0</soft_cfm>
                <soft_erp>0.2</soft_erp>
                <kp>1e+13</kp>
                <kd>1</kd>
                <max_vel>0.01</max_vel>
                <min_depth>0</min_depth>
              </ode>
              <bullet>
                <split_impulse>1</split_impulse>
                <split_impulse_penetration_threshold>-0.01</split_impulse_penetration_threshold>
                <soft_cfm>0</soft_cfm>
                <soft_erp>0.2</soft_erp>
                <kp>1e+13</kp>
                <kd>1</kd>
              </bullet>
            </contact>
          </surface>
        </collision>
      </link>
      <static>0</static>
      <allow_auto_disable>1</allow_auto_disable>
      <pose>0.195494 0.238627 0.007501 3.14154 -0.000155 8.8e-05</pose>
    </model>
    <model name='unit_cylinder_clone_1'>
      <link name='link'>
        <inertial>
          <mass>0.2</mass>
          <inertia>
            <ixx>0.0291667</ixx>
            <ixy>0</ixy>
            <ixz>0</ixz>
            <iyy>0.0291667</iyy>
            <iyz>0</iyz>
            <izz>0.025</izz>
          </inertia>
          <pose>0 0 0 0 -0 0</pose>
        </inertial>
        <self_collide>0</self_collide>
        <enable_wind>0</enable_wind>
        <kinematic>0</kinematic>
        <pose>0 -0 0 0 -0 0</pose>
        <gravity>1</gravity>
        <visual name='visual'>
          <geometry>
            <cylinder>
              <radius>0.004</radius>
              <length>0.015</length>
            </cylinder>
          </geometry>
          <material>
            <script>
              <name>Gazebo/Grey</name>
              <uri>file://media/materials/scripts/gazebo.material</uri>
            </script>
            <shader type='pixel'>
              <normal_map>__default__</normal_map>
            </shader>
            <ambient>1 0 0 1</ambient>
            <diffuse>1 0 0 1</diffuse>
            <specular>1 0 0 1</specular>
            <emissive>0 0 0 1</emissive>
          </material>
          <pose>0 0 0 0 -0 0</pose>
          <transparency>0</transparency>
          <cast_shadows>1</cast_shadows>
        </visual>
        <collision name='collision'>
          <laser_retro>0</laser_retro>
          <max_contacts>10</max_contacts>
          <pose>0 0 0 0 -0 0</pose>
          <geometry>
            <cylinder>
              <radius>0.004</radius>
              <length>0.015</length>
            </cylinder>
          </geometry>
          <surface>
            <friction>
              <ode>
                <mu>1</mu>
                <mu2>1</mu2>
                <fdir1>0 0 0</fdir1>
                <slip1>0</slip1>
                <slip2>0</slip2>
              </ode>
              <torsional>
                <coefficient>1</coefficient>
                <patch_radius>0</patch_radius>
                <surface_radius>0</surface_radius>
                <use_patch_radius>1</use_patch_radius>
                <ode>
                  <slip>0</slip>
                </ode>
              </torsional>
            </friction>
            <bounce>
              <restitution_coefficient>0</restitution_coefficient>
              <threshold>1e+06</threshold>
            </bounce>
            <contact>
              <collide_without_contact>0</collide_without_contact>
              <collide_without_contact_bitmask>1</collide_without_contact_bitmask>
              <collide_bitmask>1</collide_bitmask>
              <ode>
                <soft_cfm>0</soft_cfm>
                <soft_erp>0.2</soft_erp>
                <kp>1e+13</kp>
                <kd>1</kd>
                <max_vel>0.01</max_vel>
                <min_depth>0</min_depth>
              </ode>
              <bullet>
                <split_impulse>1</split_impulse>
                <split_impulse_penetration_threshold>-0.01</split_impulse_penetration_threshold>
                <soft_cfm>0</soft_cfm>
                <soft_erp>0.2</soft_erp>
                <kp>1e+13</kp>
                <kd>1</kd>
              </bullet>
            </contact>
          </surface>
        </collision>
      </link>
      <static>0</static>
      <allow_auto_disable>1</allow_auto_disable>
      <pose>0.385205 0.136155 0.0075 3.14159 8.2e-05 8.8e-05</pose>
    </model>
    <model name='unit_cylinder_clone_clone_clone'>
      <link name='link'>
        <inertial>
          <mass>0.2</mass>
          <inertia>
            <ixx>0.0291667</ixx>
            <ixy>0</ixy>
            <ixz>0</ixz>
            <iyy>0.0291667</iyy>
            <iyz>0</iyz>
            <izz>0.025</izz>
          </inertia>
          <pose>0 0 0 0 -0 0</pose>
        </inertial>
        <self_collide>0</self_collide>
        <enable_wind>0</enable_wind>
        <kinematic>0</kinematic>
        <pose>0 0 0 0 -0 0</pose>
        <gravity>1</gravity>
        <visual name='visual'>
          <geometry>
            <cylinder>
              <radius>0.004</radius>
              <length>0.015</length>
            </cylinder>
          </geometry>
          <material>
            <script>
              <name>Gazebo/Grey</name>
              <uri>file://media/materials/scripts/gazebo.material</uri>
            </script>
            <shader type='pixel'>
              <normal_map>__default__</normal_map>
            </shader>
            <ambient>0 0 1 1</ambient>
            <diffuse>0 0 1 1</diffuse>
            <specular>0 0 0.9 1</specular>
            <emissive>0 0 0 1</emissive>
          </material>
          <pose>0 0 0 0 -0 0</pose>
          <transparency>0</transparency>
          <cast_shadows>1</cast_shadows>
        </visual>
        <collision name='collision'>
          <laser_retro>0</laser_retro>
          <max_contacts>10</max_contacts>
          <pose>0 0 0 0 -0 0</pose>
          <geometry>
            <cylinder>
              <radius>0.004</radius>
              <length>0.015</length>
            </cylinder>
          </geometry>
          <surface>
            <friction>
              <ode>
                <mu>1</mu>
                <mu2>1</mu2>
                <fdir1>0 0 0</fdir1>
                <slip1>0</slip1>
                <slip2>0</slip2>
              </ode>
              <torsional>
                <coefficient>1</coefficient>
                <patch_radius>0</patch_radius>
                <surface_radius>0</surface_radius>
                <use_patch_radius>1</use_patch_radius>
                <ode>
                  <slip>0</slip>
                </ode>
              </torsional>
            </friction>
            <bounce>
              <restitution_coefficient>0</restitution_coefficient>
              <threshold>1e+06</threshold>
            </bounce>
            <contact>
              <collide_without_contact>0</collide_without_contact>
              <collide_without_contact_bitmask>1</collide_without_contact_bitmask>
              <collide_bitmask>1</collide_bitmask>
              <ode>
                <soft_cfm>0</soft_cfm>
                <soft_erp>0.2</soft_erp>
                <kp>1e+13</kp>
                <kd>1</kd>
                <max_vel>0.01</max_vel>
                <min_depth>0</min_depth>
              </ode>
              <bullet>
                <split_impulse>1</split_impulse>
                <split_impulse_penetration_threshold>-0.01</split_impulse_penetration_threshold>
                <soft_cfm>0</soft_cfm>
                <soft_erp>0.2</soft_erp>
                <kp>1e+13</kp>
                <kd>1</kd>
              </bullet>
            </contact>
          </surface>
        </collision>
      </link>
      <static>0</static>
      <allow_auto_disable>1</allow_auto_disable>
      <pose>-0.000535 1.2249 0.007501 3.14154 -0.000155 8.8e-05</pose>
    </model>
    <gui fullscreen='0'>
      <camera name='user_camera'>
        <pose>-0.273179 -0.967729 0.376708 0 0.170143 1.34888</pose>
        <view_controller>orbit</view_controller>
        <projection_type>perspective</projection_type>
      </camera>
    </gui>
  </world>
</sdf>
