<robot name="onshape">
<link name="gg_head">
<visual>
<origin xyz="0.0087642696920541378336 0.17590937888457450211 -0.077003151707980527219" rpy="1.6298183611939731641 -0.041056855101145567355 0.16375605659172978723" />
<geometry>
<mesh filename="package:///part_1.stl"/>
</geometry>
<material name="part_1_material">
<color rgba="0.43921568627450979783 0.47450980392156860699 0.50196078431372548323 1.0"/>
</material>
</visual>
<collision>
<origin xyz="0.0087642696920541378336 0.17590937888457450211 -0.077003151707980527219" rpy="1.6298183611939731641 -0.041056855101145567355 0.16375605659172978723" />
<geometry>
<mesh filename="package:///part_1.stl"/>
</geometry>
</collision>
<visual>
<origin xyz="0.34403879800602688022 0.17113271177364089426 0.092454118547484309687" rpy="1.511774292395820174 0.041056855101145685316 -2.9778365969980629124" />
<geometry>
<mesh filename="package:///mg995_v3.stl"/>
</geometry>
<material name="mg995_v3_material">
<color rgba="0.62745098039215685404 0.62745098039215685404 0.62745098039215685404 1.0"/>
</material>
</visual>
<collision>
<origin xyz="0.34403879800602688022 0.17113271177364089426 0.092454118547484309687" rpy="1.511774292395820174 0.041056855101145685316 -2.9778365969980629124" />
<geometry>
<mesh filename="package:///mg995_v3.stl"/>
</geometry>
</collision>
<visual>
<origin xyz="0.052820857097337123309 0.1224814247491170377 -0.079117583806706234806" rpy="1.6298183611939731641 -0.041056855101145733888 0.16375605659173023132" />
<geometry>
<mesh filename="package:///part_1.stl"/>
</geometry>
<material name="part_1_material">
<color rgba="0.43921568627450979783 0.47450980392156860699 0.50196078431372548323 1.0"/>
</material>
</visual>
<collision>
<origin xyz="0.052820857097337123309 0.1224814247491170377 -0.079117583806706234806" rpy="1.6298183611939731641 -0.041056855101145733888 0.16375605659173023132" />
<geometry>
<mesh filename="package:///part_1.stl"/>
</geometry>
</collision>
<visual>
<origin xyz="-0.38478954630556638783 0.030628415788801231778 0.060802059058618282417" rpy="1.6298183611939731641 -0.041056855101145713072 0.16375605659173067541" />
<geometry>
<mesh filename="package:///mg995_v3.stl"/>
</geometry>
<material name="mg995_v3_material">
<color rgba="0.62745098039215685404 0.62745098039215685404 0.62745098039215685404 1.0"/>
</material>
</visual>
<collision>
<origin xyz="-0.38478954630556638783 0.030628415788801231778 0.060802059058618282417" rpy="1.6298183611939731641 -0.041056855101145713072 0.16375605659173067541" />
<geometry>
<mesh filename="package:///mg995_v3.stl"/>
</geometry>
</collision>
<visual>
<origin xyz="-0.26360839842624722573 -0.012171699006146910471 -0.072585728216011113911" rpy="3.1382040391284218295 -0.071804211987078134238 1.1746470986379109469" />
<geometry>
<mesh filename="package:///part_3.stl"/>
</geometry>
<material name="part_3_material">
<color rgba="0.26274509803921569651 0.28235294117647058432 0.30196078431372547213 1.0"/>
</material>
</visual>
<collision>
<origin xyz="-0.26360839842624722573 -0.012171699006146910471 -0.072585728216011113911" rpy="3.1382040391284218295 -0.071804211987078134238 1.1746470986379109469" />
<geometry>
<mesh filename="package:///part_3.stl"/>
</geometry>
</collision>
<visual>
<origin xyz="0.22340394124179629998 -0.179192526628497939 0.06594044179429270347" rpy="1.5057047502754277168 -0.030523938227598110956 2.2603571641492261612" />
<geometry>
<mesh filename="package:///mg995_v3.stl"/>
</geometry>
<material name="mg995_v3_material">
<color rgba="0.62745098039215685404 0.62745098039215685404 0.62745098039215685404 1.0"/>
</material>
</visual>
<collision>
<origin xyz="0.22340394124179629998 -0.179192526628497939 0.06594044179429270347" rpy="1.5057047502754277168 -0.030523938227598110956 2.2603571641492261612" />
<geometry>
<mesh filename="package:///mg995_v3.stl"/>
</geometry>
</collision>
<visual>
<origin xyz="0.25823038360233252497 -0.37034578902856662985 -0.34494944053760745462" rpy="1.5057047502754270507 -0.030523938227597934014 2.2603571641492261612" />
<geometry>
<mesh filename="package:///part_13.stl"/>
</geometry>
<material name="part_13_material">
<color rgba="0.49803921568627451677 0.49803921568627451677 0.49803921568627451677 1.0"/>
</material>
</visual>
<collision>
<origin xyz="0.25823038360233252497 -0.37034578902856662985 -0.34494944053760745462" rpy="1.5057047502754270507 -0.030523938227597934014 2.2603571641492261612" />
<geometry>
<mesh filename="package:///part_13.stl"/>
</geometry>
</collision>
<visual>
<origin xyz="0.10025948261446183951 0.45120580218335987199 0.10314176555624292309" rpy="1.5768892466724602208 0.071625747184156512981 -1.9292085952769881807" />
<geometry>
<mesh filename="package:///mg995_v3.stl"/>
</geometry>
<material name="mg995_v3_material">
<color rgba="0.62745098039215685404 0.62745098039215685404 0.62745098039215685404 1.0"/>
</material>
</visual>
<collision>
<origin xyz="0.10025948261446183951 0.45120580218335987199 0.10314176555624292309" rpy="1.5768892466724602208 0.071625747184156512981 -1.9292085952769881807" />
<geometry>
<mesh filename="package:///mg995_v3.stl"/>
</geometry>
</collision>
<visual>
<origin xyz="-0.058300929378772861633 0.16721931887512520021 -0.11974355332778900685" rpy="-1.5768892466724604429 -0.071625747184156651759 1.2123840583128058235" />
<geometry>
<mesh filename="package:///part_1.stl"/>
</geometry>
<material name="part_1_material">
<color rgba="0.43921568627450979783 0.47450980392156860699 0.50196078431372548323 1.0"/>
</material>
</visual>
<collision>
<origin xyz="-0.058300929378772861633 0.16721931887512520021 -0.11974355332778900685" rpy="-1.5768892466724604429 -0.071625747184156651759 1.2123840583128058235" />
<geometry>
<mesh filename="package:///part_1.stl"/>
</geometry>
</collision>
<visual>
<origin xyz="-0.57198902066263790367 0.1458665971628741731 -0.33701632232972117409" rpy="1.6298183611939738302 -0.041056855101145803277 0.1637560565917303701" />
<geometry>
<mesh filename="package:///part_13.stl"/>
</geometry>
<material name="part_13_material">
<color rgba="0.49803921568627451677 0.49803921568627451677 0.49803921568627451677 1.0"/>
</material>
</visual>
<collision>
<origin xyz="-0.57198902066263790367 0.1458665971628741731 -0.33701632232972117409" rpy="1.6298183611939738302 -0.041056855101145803277 0.1637560565917303701" />
<geometry>
<mesh filename="package:///part_13.stl"/>
</geometry>
</collision>
<visual>
<origin xyz="-0.27442619398983725265 0.62381499882157109838 -0.29673609623299412874" rpy="1.6358879033143658432 0.030523938227597857686 -0.88123548944056750987" />
<geometry>
<mesh filename="package:///part_13.stl"/>
</geometry>
<material name="part_13_material">
<color rgba="0.49803921568627451677 0.49803921568627451677 0.49803921568627451677 1.0"/>
</material>
</visual>
<collision>
<origin xyz="-0.27442619398983725265 0.62381499882157109838 -0.29673609623299412874" rpy="1.6358879033143658432 0.030523938227597857686 -0.88123548944056750987" />
<geometry>
<mesh filename="package:///part_13.stl"/>
</geometry>
</collision>
<visual>
<origin xyz="0.26920659275336772387 0.24533684236022135217 -0.11858216730036477693" rpy="-3.1382040391284427017 0.071804211987079119561 -1.96694555495217549" />
<geometry>
<mesh filename="package:///part_5.stl"/>
</geometry>
<material name="part_5_material">
<color rgba="1 0 0 1.0"/>
</material>
</visual>
<collision>
<origin xyz="0.26920659275336772387 0.24533684236022135217 -0.11858216730036477693" rpy="-3.1382040391284427017 0.071804211987079119561 -1.96694555495217549" />
<geometry>
<mesh filename="package:///part_5.stl"/>
</geometry>
</collision>
<visual>
<origin xyz="-0.082541909320956244334 0.10250616885917371301 -0.12470168870872204436" rpy="-1.5057047502754266066 0.030523938227598003403 -0.88123548944056728782" />
<geometry>
<mesh filename="package:///part_1.stl"/>
</geometry>
<material name="part_1_material">
<color rgba="0.43921568627450979783 0.47450980392156860699 0.50196078431372548323 1.0"/>
</material>
</visual>
<collision>
<origin xyz="-0.082541909320956244334 0.10250616885917371301 -0.12470168870872204436" rpy="-1.5057047502754266066 0.030523938227598003403 -0.88123548944056728782" />
<geometry>
<mesh filename="package:///part_1.stl"/>
</geometry>
</collision>
<visual>
<origin xyz="-0.14101023091400030629 -0.24944467462091787779 0.050114412049859682896" rpy="1.5647034069173328952 -0.071625747184156443592 1.2123840583128053794" />
<geometry>
<mesh filename="package:///mg995_v3.stl"/>
</geometry>
<material name="mg995_v3_material">
<color rgba="0.62745098039215685404 0.62745098039215685404 0.62745098039215685404 1.0"/>
</material>
</visual>
<collision>
<origin xyz="-0.14101023091400030629 -0.24944467462091787779 0.050114412049859682896" rpy="1.5647034069173328952 -0.071625747184156443592 1.2123840583128053794" />
<geometry>
<mesh filename="package:///mg995_v3.stl"/>
</geometry>
</collision>
<visual>
<origin xyz="-0.015476710250128894453 0.1111962288686231537 -0.08196128708891353698" rpy="1.6358879033143658432 0.030523938227597979117 -0.8812354894405671768" />
<geometry>
<mesh filename="package:///part_1.stl"/>
</geometry>
<material name="part_1_material">
<color rgba="0.99215686274509806708 0.0039215686274509803377 0.0039215686274509803377 1.0"/>
</material>
</visual>
<collision>
<origin xyz="-0.015476710250128894453 0.1111962288686231537 -0.08196128708891353698" rpy="1.6358879033143658432 0.030523938227597979117 -0.8812354894405671768" />
<geometry>
<mesh filename="package:///part_1.stl"/>
</geometry>
</collision>
<visual>
<origin xyz="0.55579321027512740283 0.10760261263013101707 -0.3046692144408805758" rpy="1.5117742923958199519 0.041056855101145608988 -2.9778365969980629124" />
<geometry>
<mesh filename="package:///part_13.stl"/>
</geometry>
<material name="part_13_material">
<color rgba="0.49803921568627451677 0.49803921568627451677 0.49803921568627451677 1.0"/>
</material>
</visual>
<collision>
<origin xyz="0.55579321027512740283 0.10760261263013101707 -0.3046692144408805758" rpy="1.5117742923958199519 0.041056855101145608988 -2.9778365969980629124" />
<geometry>
<mesh filename="package:///part_13.stl"/>
</geometry>
</collision>
<visual>
<origin xyz="-0.30566073186654979521 -0.35121379676219788291 -0.36112299448202800356" rpy="1.5647034069173328952 -0.071625747184156401959 1.2123840583128056014" />
<geometry>
<mesh filename="package:///part_13.stl"/>
</geometry>
<material name="part_13_material">
<color rgba="0.49803921568627451677 0.49803921568627451677 0.49803921568627451677 1.0"/>
</material>
</visual>
<collision>
<origin xyz="-0.30566073186654979521 -0.35121379676219788291 -0.36112299448202800356" rpy="1.5647034069173328952 -0.071625747184156401959 1.2123840583128056014" />
<geometry>
<mesh filename="package:///part_13.stl"/>
</geometry>
</collision>
<visual>
<origin xyz="-0.3291585625687195038 0.13731822473850138766 0.03436960639698199288" rpy="0.066192106571393530268 0.028054638248618105068 -0.84366007373370432987" />
<geometry>
<mesh filename="package:///part_5.stl"/>
</geometry>
<material name="part_5_material">
<color rgba="1 0 0 1.0"/>
</material>
</visual>
<collision>
<origin xyz="-0.3291585625687195038 0.13731822473850138766 0.03436960639698199288" rpy="0.066192106571393530268 0.028054638248618105068 -0.84366007373370432987" />
<geometry>
<mesh filename="package:///part_5.stl"/>
</geometry>
</collision>
<visual>
<origin xyz="-0.26415468954133458634 0.38095365419094029402 0.087315735811809874756" rpy="1.6358879033143658432 0.030523938227597979117 -0.8812354894405671768" />
<geometry>
<mesh filename="package:///mg995_v3.stl"/>
</geometry>
<material name="mg995_v3_material">
<color rgba="0.62745098039215685404 0.62745098039215685404 0.62745098039215685404 1.0"/>
</material>
</visual>
<collision>
<origin xyz="-0.26415468954133458634 0.38095365419094029402 0.087315735811809874756" rpy="1.6358879033143658432 0.030523938227597979117 -0.8812354894405671768" />
<geometry>
<mesh filename="package:///mg995_v3.stl"/>
</geometry>
</collision>
<visual>
<origin xyz="-0.039717690192312013475 0.046483078852671791403 -0.086919422469846546742" rpy="1.5117742923958199519 0.041056855101145720011 -2.9778365969980629124" />
<geometry>
<mesh filename="package:///part_1.stl"/>
</geometry>
<material name="part_1_material">
<color rgba="0.43921568627450979783 0.47450980392156860699 0.50196078431372548323 1.0"/>
</material>
</visual>
<collision>
<origin xyz="-0.039717690192312013475 0.046483078852671791403 -0.086919422469846546742" rpy="1.5117742923958199519 0.041056855101145720011 -2.9778365969980629124" />
<geometry>
<mesh filename="package:///part_1.stl"/>
</geometry>
</collision>
<visual>
<origin xyz="0.02857987715515411184 0.057768274733165668466 -0.084075719187639258445" rpy="1.6298183611939733861 -0.041056855101145720011 0.16375605659173003703" />
<geometry>
<mesh filename="package:///part_1.stl"/>
</geometry>
<material name="part_1_material">
<color rgba="0.43921568627450979783 0.47450980392156860699 0.50196078431372548323 1.0"/>
</material>
</visual>
<collision>
<origin xyz="0.02857987715515411184 0.057768274733165668466 -0.084075719187639258445" rpy="1.6298183611939733861 -0.041056855101145720011 0.16375605659173003703" />
<geometry>
<mesh filename="package:///part_1.stl"/>
</geometry>
</collision>
<visual>
<origin xyz="0.289464921479042403 0.60468300655519890974 -0.28056254228857374633" rpy="1.5768892466724602208 0.071625747184156554614 -1.9292085952769881807" />
<geometry>
<mesh filename="package:///part_13.stl"/>
</geometry>
<material name="part_13_material">
<color rgba="0.49803921568627451677 0.49803921568627451677 0.49803921568627451677 1.0"/>
</material>
</visual>
<collision>
<origin xyz="0.289464921479042403 0.60468300655519890974 -0.28056254228857374633" rpy="1.5768892466724602208 0.071625747184156554614 -1.9292085952769881807" />
<geometry>
<mesh filename="package:///part_13.stl"/>
</geometry>
</collision>
<inertial>
<origin xyz="-0.015132849479904401241 0.11233298917452018417 -0.094153134482988967702" rpy="0 0 0"/>
<mass value="1.2784264529325646276" />
<inertia ixx="0.0034490153936869920141" ixy="2.8595055435070616551e-05"  ixz="-5.8954517689590812631e-05" iyy="0.0033407825590690523772" iyz="-0.00015297537439560429987" izz="0.0053798596339990293475" />
</inertial>
</link>

<link name="gg_leg_base">
<visual>
<origin xyz="-0.30299741173028010843 -0.21950000000000008393 -0.015497759461402957348" rpy="8.1999207304032796966e-17 -1.1201552895456483168e-16 2.2907265424388540914e-16" />
<geometry>
<mesh filename="package:///part_11.stl"/>
</geometry>
<material name="part_11_material">
<color rgba="0.49803921568627451677 0.49803921568627451677 0.49803921568627451677 1.0"/>
</material>
</visual>
<collision>
<origin xyz="-0.30299741173028010843 -0.21950000000000008393 -0.015497759461402957348" rpy="8.1999207304032796966e-17 -1.1201552895456483168e-16 2.2907265424388540914e-16" />
<geometry>
<mesh filename="package:///part_11.stl"/>
</geometry>
</collision>
<visual>
<origin xyz="-0.13214254961996313442 -0.010002240538597106934 -0.044999999999999998335" rpy="1.570796326794896558 -1.3516261297905956521e-18 -2.1281469973019503709e-17" />
<geometry>
<mesh filename="package:///part_6.stl"/>
</geometry>
<material name="part_6_material">
<color rgba="0.91764705882352937127 0.91764705882352937127 0.91764705882352937127 1.0"/>
</material>
</visual>
<collision>
<origin xyz="-0.13214254961996313442 -0.010002240538597106934 -0.044999999999999998335" rpy="1.570796326794896558 -1.3516261297905956521e-18 -2.1281469973019503709e-17" />
<geometry>
<mesh filename="package:///part_6.stl"/>
</geometry>
</collision>
<visual>
<origin xyz="-0.30390026077865617271 0.17900000000000004796 -0.015497759461402901837" rpy="8.1999207304032821618e-17 -7.7464419290125258153e-17 -2.3553439774560365875e-16" />
<geometry>
<mesh filename="package:///mg995_v3.stl"/>
</geometry>
<material name="mg995_v3_material">
<color rgba="0.62745098039215685404 0.62745098039215685404 0.62745098039215685404 1.0"/>
</material>
</visual>
<collision>
<origin xyz="-0.30390026077865617271 0.17900000000000004796 -0.015497759461402901837" rpy="8.1999207304032821618e-17 -7.7464419290125258153e-17 -2.3553439774560365875e-16" />
<geometry>
<mesh filename="package:///mg995_v3.stl"/>
</geometry>
</collision>
<inertial>
<origin xyz="-0.063706673597089674699 -0.00036253314902457209465 -0.025527945142445593318" rpy="0 0 0"/>
<mass value="0.084196217898659775347" />
<inertia ixx="2.7957377169670465393e-05" ixy="-7.7137426145837235882e-07"  ixz="1.8403677325147274561e-07" iyy="9.7805049098283154208e-05" iyz="3.2099813099687639615e-09" izz="9.8669146380223724684e-05" />
</inertial>
</link>

<link name="gg_leg_middle">
<visual>
<origin xyz="-0.3029974117302799419 -0.010002240538597523267 -0.24499999999999988454" rpy="1.5707963267948952257 6.719687322833366729e-16 4.1802014772509565086e-16" />
<geometry>
<mesh filename="package:///part_11.stl"/>
</geometry>
<material name="part_11_material">
<color rgba="0.49803921568627451677 0.49803921568627451677 0.49803921568627451677 1.0"/>
</material>
</visual>
<collision>
<origin xyz="-0.3029974117302799419 -0.010002240538597523267 -0.24499999999999988454" rpy="1.5707963267948952257 6.719687322833366729e-16 4.1802014772509565086e-16" />
<geometry>
<mesh filename="package:///part_11.stl"/>
</geometry>
</collision>
<visual>
<origin xyz="-0.13214254961996318993 -0.010002240538597106934 -0.04500000000000002609" rpy="1.570796326794896558 -6.0111246971306447659e-18 -4.1951326079425937121e-18" />
<geometry>
<mesh filename="package:///part_6.stl"/>
</geometry>
<material name="part_6_material">
<color rgba="0.91764705882352937127 0.91764705882352937127 0.91764705882352937127 1.0"/>
</material>
</visual>
<collision>
<origin xyz="-0.13214254961996318993 -0.010002240538597106934 -0.04500000000000002609" rpy="1.570796326794896558 -6.0111246971306447659e-18 -4.1951326079425937121e-18" />
<geometry>
<mesh filename="package:///part_6.stl"/>
</geometry>
</collision>
<visual>
<origin xyz="-0.30390026077865572862 -0.010002240538597009789 0.15350000000000019185" rpy="1.5707963267948954478 7.7999262360942981871e-16 4.041583788234221836e-16" />
<geometry>
<mesh filename="package:///mg995_v3.stl"/>
</geometry>
<material name="mg995_v3_material">
<color rgba="0.62745098039215685404 0.62745098039215685404 0.62745098039215685404 1.0"/>
</material>
</visual>
<collision>
<origin xyz="-0.30390026077865572862 -0.010002240538597009789 0.15350000000000019185" rpy="1.5707963267948954478 7.7999262360942981871e-16 4.041583788234221836e-16" />
<geometry>
<mesh filename="package:///mg995_v3.stl"/>
</geometry>
</collision>
<inertial>
<origin xyz="-0.063706673597089494288 -3.8498478454065103725e-06 -0.025894328139315556797" rpy="0 0 0"/>
<mass value="0.084196217898659775347" />
<inertia ixx="2.7955415541966263405e-05" ixy="-1.3492807390252700798e-08"  ixz="-6.0083029559708784355e-07" iyy="0.00010348466964737586759" iyz="-2.2291674578699577307e-09" izz="9.2987564203425620082e-05" />
</inertial>
</link>

<link name="gg_leg_middle_2">
<visual>
<origin xyz="-0.30299741173027966434 -0.010002240538597148567 -0.24500000000000016209" rpy="1.570796326794896558 -6.3659791568303078838e-16 1.4054954524753705213e-16" />
<geometry>
<mesh filename="package:///part_11.stl"/>
</geometry>
<material name="part_11_material">
<color rgba="0.49803921568627451677 0.49803921568627451677 0.49803921568627451677 1.0"/>
</material>
</visual>
<collision>
<origin xyz="-0.30299741173027966434 -0.010002240538597148567 -0.24500000000000016209" rpy="1.570796326794896558 -6.3659791568303078838e-16 1.4054954524753705213e-16" />
<geometry>
<mesh filename="package:///part_11.stl"/>
</geometry>
</collision>
<visual>
<origin xyz="-0.13214254961996318993 -0.010002240538597120811 -0.045000000000000012212" rpy="1.570796326794896558 9.2421866318581015233e-18 1.9919492019124694145e-18" />
<geometry>
<mesh filename="package:///part_6.stl"/>
</geometry>
<material name="part_6_material">
<color rgba="0.91764705882352937127 0.91764705882352937127 0.91764705882352937127 1.0"/>
</material>
</visual>
<collision>
<origin xyz="-0.13214254961996318993 -0.010002240538597120811 -0.045000000000000012212" rpy="1.570796326794896558 9.2421866318581015233e-18 1.9919492019124694145e-18" />
<geometry>
<mesh filename="package:///part_6.stl"/>
</geometry>
</collision>
<visual>
<origin xyz="-0.30390026077865600618 -0.010002240538597106934 0.1534999999999999698" rpy="1.570796326794896558 2.9789185750181759047e-17 -1.0877860236629461644e-16" />
<geometry>
<mesh filename="package:///mg995_v3.stl"/>
</geometry>
<material name="mg995_v3_material">
<color rgba="0.62745098039215685404 0.62745098039215685404 0.62745098039215685404 1.0"/>
</material>
</visual>
<collision>
<origin xyz="-0.30390026077865600618 -0.010002240538597106934 0.1534999999999999698" rpy="1.570796326794896558 2.9789185750181759047e-17 -1.0877860236629461644e-16" />
<geometry>
<mesh filename="package:///mg995_v3.stl"/>
</geometry>
</collision>
<inertial>
<origin xyz="-0.063706673597089577554 -3.8498478453988811468e-06 -0.025894328139315549858" rpy="0 0 0"/>
<mass value="0.084196217898659775347" />
<inertia ixx="2.7955415541966263405e-05" ixy="-1.3492807390230393391e-08"  ixz="-6.0083029559712659531e-07" iyy="0.00010348466964737611153" iyz="-2.2291674578640955017e-09" izz="9.2987564203425836923e-05" />
</inertial>
</link>

<link name="gg_leg_tip">
<visual>
<origin xyz="-0.13214254961996318993 -0.010002240538597106934 -0.044999999999999998335" rpy="1.570796326794896558 -3.761290594646183435e-18 1.2099091451812698266e-18" />
<geometry>
<mesh filename="package:///part_6.stl"/>
</geometry>
<material name="part_6_material">
<color rgba="0.91764705882352937127 0.91764705882352937127 0.91764705882352937127 1.0"/>
</material>
</visual>
<collision>
<origin xyz="-0.13214254961996318993 -0.010002240538597106934 -0.044999999999999998335" rpy="1.570796326794896558 -3.761290594646183435e-18 1.2099091451812698266e-18" />
<geometry>
<mesh filename="package:///part_6.stl"/>
</geometry>
</collision>
<visual>
<origin xyz="-0.12259449000000011143 0.0098031712025948430922 -0.025281761415826442541" rpy="-1.5707963267948863439 1.570796326794896336 0" />
<geometry>
<mesh filename="package:///led_3mm_trans.stl"/>
</geometry>
<material name="led_3mm_trans_material">
<color rgba="1 1 1 1.0"/>
</material>
</visual>
<collision>
<origin xyz="-0.12259449000000011143 0.0098031712025948430922 -0.025281761415826442541" rpy="-1.5707963267948863439 1.570796326794896336 0" />
<geometry>
<mesh filename="package:///led_3mm_trans.stl"/>
</geometry>
</collision>
<visual>
<origin xyz="-0.12029449000000014269 0.010865472711805254646 -0.024348211468834160542" rpy="3.1415926535897900074 -8.5762806767711440708e-17 -1.5707963267949041075" />
<geometry>
<mesh filename="package:///pulsador.stl"/>
</geometry>
<material name="pulsador_material">
<color rgba="1 0 0 1.0"/>
</material>
</visual>
<collision>
<origin xyz="-0.12029449000000014269 0.010865472711805254646 -0.024348211468834160542" rpy="3.1415926535897900074 -8.5762806767711440708e-17 -1.5707963267949041075" />
<geometry>
<mesh filename="package:///pulsador.stl"/>
</geometry>
</collision>
<visual>
<origin xyz="-0.026494490000000037178 0.14717946631849004868 -0.050978735407716746497" rpy="3.141592653589793116 -5.4210429599613795521e-17 1.570796326794896558" />
<geometry>
<mesh filename="package:///part_25.stl"/>
</geometry>
<material name="part_25_material">
<color rgba="0.30196078431372547213 0.29019607843137257275 0.26274509803921569651 1.0"/>
</material>
</visual>
<collision>
<origin xyz="-0.026494490000000037178 0.14717946631849004868 -0.050978735407716746497" rpy="3.141592653589793116 -5.4210429599613795521e-17 1.570796326794896558" />
<geometry>
<mesh filename="package:///part_25.stl"/>
</geometry>
</collision>
<inertial>
<origin xyz="-0.058600447713097768287 0.00030798747790677054445 -0.025499135322571434004" rpy="0 0 0"/>
<mass value="0.15555503524263536441" />
<inertia ixx="4.2100962384746052746e-05" ixy="5.2877209940367814821e-06"  ixz="2.0615243018217577333e-07" iyy="0.0001594027808123643121" iyz="2.8650165663787223923e-08" izz="0.00015063387305898015165" />
</inertial>
</link>

<joint name="lm4" type="revolute">
<origin xyz="-0.093900260629645460053 -2.2405385971119295974e-06 -3.6082248300317587564e-16" rpy="1.1591028931883329211e-16 1.3987013019721388441e-15 0.011232442213759248617" />
<parent link="gg_leg_middle_2" />
<child link="gg_leg_tip" />
<axis xyz="0 0 1"/>
<limit effort="1" velocity="20" />
<joint_properties friction="0.0"/>
</joint>

<joint name="lm3" type="revolute">
<origin xyz="-0.093900260629644405341 -2.2405385971258073852e-06 8.3266726846886740532e-17" rpy="-1.8954057592443064974e-15 5.066707613585821167e-15 0.0011334544965999478975" />
<parent link="gg_leg_middle" />
<child link="gg_leg_middle_2" />
<axis xyz="0 0 1"/>
<limit effort="1" velocity="20" />
<joint_properties friction="0.0"/>
</joint>

<joint name="lm2" type="revolute">
<origin xyz="-0.093900260629649512367 0.025499999999999689582 -0.02549775946140271643" rpy="-1.5707963267948974462 0.0068254400670025713524 3.8839560872755836875e-15" />
<parent link="gg_leg_base" />
<child link="gg_leg_middle" />
<axis xyz="0 0 1"/>
<limit effort="1" velocity="20" />
<joint_properties friction="0.0"/>
</joint>

<joint name="lm1" type="revolute">
<origin xyz="-0.17469563433045029455 0.084638773847993453714 -0.083092622691246842415" rpy="0.057202001338504185335 -0.043558110119680693018 0.20678140893656210553" />
<parent link="gg_head" />
<child link="gg_leg_base" />
<axis xyz="0 0 1"/>
<limit effort="1" velocity="20" />
<joint_properties friction="0.0"/>
</joint>

<link name="gg_leg_base_2">
<visual>
<origin xyz="-0.3029974117302799419 -0.21949999999999980638 -0.015497759461402943471" rpy="1.0671104324833608229e-16 -1.0406358507593688889e-16 1.495996524646683313e-17" />
<geometry>
<mesh filename="package:///part_11.stl"/>
</geometry>
<material name="part_11_material">
<color rgba="0.49803921568627451677 0.49803921568627451677 0.49803921568627451677 1.0"/>
</material>
</visual>
<collision>
<origin xyz="-0.3029974117302799419 -0.21949999999999980638 -0.015497759461402943471" rpy="1.0671104324833608229e-16 -1.0406358507593688889e-16 1.495996524646683313e-17" />
<geometry>
<mesh filename="package:///part_11.stl"/>
</geometry>
</collision>
<visual>
<origin xyz="-0.13214254961996321769 -0.010002240538597093056 -0.045000000000000012212" rpy="1.570796326794896558 -8.940513607405499832e-18 -7.4959414881096840766e-17" />
<geometry>
<mesh filename="package:///part_6.stl"/>
</geometry>
<material name="part_6_material">
<color rgba="0.91764705882352937127 0.91764705882352937127 0.91764705882352937127 1.0"/>
</material>
</visual>
<collision>
<origin xyz="-0.13214254961996321769 -0.010002240538597093056 -0.045000000000000012212" rpy="1.570796326794896558 -8.940513607405499832e-18 -7.4959414881096840766e-17" />
<geometry>
<mesh filename="package:///part_6.stl"/>
</geometry>
</collision>
<visual>
<origin xyz="-0.30390026077865572862 0.17899999999999982592 -0.015497759461402901837" rpy="-4.5622062963655721754e-17 -3.4818005891961099517e-17 1.9079804760935808202e-16" />
<geometry>
<mesh filename="package:///mg995_v3.stl"/>
</geometry>
<material name="mg995_v3_material">
<color rgba="0.62745098039215685404 0.62745098039215685404 0.62745098039215685404 1.0"/>
</material>
</visual>
<collision>
<origin xyz="-0.30390026077865572862 0.17899999999999982592 -0.015497759461402901837" rpy="-4.5622062963655721754e-17 -3.4818005891961099517e-17 1.9079804760935808202e-16" />
<geometry>
<mesh filename="package:///mg995_v3.stl"/>
</geometry>
</collision>
<inertial>
<origin xyz="-0.063706673597089563676 -0.00036253314902456802889 -0.025527945142445589849" rpy="0 0 0"/>
<mass value="0.084196217898659775347" />
<inertia ixx="2.7957377169670438288e-05" ixy="-7.7137426145838273497e-07"  ixz="1.8403677325148987156e-07" iyy="9.7805049098282639212e-05" iyz="3.2099813099656339101e-09" izz="9.8669146380223263899e-05" />
</inertial>
</link>

<link name="gg_leg_middle_3">
<visual>
<origin xyz="-0.30299741173028027497 -0.010002240538597023667 -0.244999999999999718" rpy="1.570796326794896558 9.850682351462620822e-16 -4.4603756710149438103e-16" />
<geometry>
<mesh filename="package:///part_11.stl"/>
</geometry>
<material name="part_11_material">
<color rgba="0.49803921568627451677 0.49803921568627451677 0.49803921568627451677 1.0"/>
</material>
</visual>
<collision>
<origin xyz="-0.30299741173028027497 -0.010002240538597023667 -0.244999999999999718" rpy="1.570796326794896558 9.850682351462620822e-16 -4.4603756710149438103e-16" />
<geometry>
<mesh filename="package:///part_11.stl"/>
</geometry>
</collision>
<visual>
<origin xyz="-0.13214254961996318993 -0.010002240538597093056 -0.044999999999999984457" rpy="1.570796326794896558 1.0422901373762247624e-16 -6.3664250307130748414e-18" />
<geometry>
<mesh filename="package:///part_6.stl"/>
</geometry>
<material name="part_6_material">
<color rgba="0.91764705882352937127 0.91764705882352937127 0.91764705882352937127 1.0"/>
</material>
</visual>
<collision>
<origin xyz="-0.13214254961996318993 -0.010002240538597093056 -0.044999999999999984457" rpy="1.570796326794896558 1.0422901373762247624e-16 -6.3664250307130748414e-18" />
<geometry>
<mesh filename="package:///part_6.stl"/>
</geometry>
</collision>
<visual>
<origin xyz="-0.30390026077865606169 -0.010002240538597079178 0.15350000000000002531" rpy="1.57079632679489678 -2.8128868904498634841e-18 -2.4166237004739903639e-16" />
<geometry>
<mesh filename="package:///mg995_v3.stl"/>
</geometry>
<material name="mg995_v3_material">
<color rgba="0.62745098039215685404 0.62745098039215685404 0.62745098039215685404 1.0"/>
</material>
</visual>
<collision>
<origin xyz="-0.30390026077865606169 -0.010002240538597079178 0.15350000000000002531" rpy="1.57079632679489678 -2.8128868904498634841e-18 -2.4166237004739903639e-16" />
<geometry>
<mesh filename="package:///mg995_v3.stl"/>
</geometry>
</collision>
<inertial>
<origin xyz="-0.063706673597089646943 -3.8498478453788522057e-06 -0.025894328139315501286" rpy="0 0 0"/>
<mass value="0.084196217898659775347" />
<inertia ixx="2.7955415541966270181e-05" ixy="-1.349280739021603519e-08"  ixz="-6.0083029559707545569e-07" iyy="0.00010348466964737616574" iyz="-2.2291674578623323662e-09" izz="9.2987564203425918238e-05" />
</inertial>
</link>

<link name="gg_leg_middle_4">
<visual>
<origin xyz="-0.30299741173027999741 -0.010002240538597079178 -0.24499999999999988454" rpy="1.570796326794896558 2.2997337704766587599e-16 -9.7722527226103045842e-17" />
<geometry>
<mesh filename="package:///part_11.stl"/>
</geometry>
<material name="part_11_material">
<color rgba="0.49803921568627451677 0.49803921568627451677 0.49803921568627451677 1.0"/>
</material>
</visual>
<collision>
<origin xyz="-0.30299741173027999741 -0.010002240538597079178 -0.24499999999999988454" rpy="1.570796326794896558 2.2997337704766587599e-16 -9.7722527226103045842e-17" />
<geometry>
<mesh filename="package:///part_11.stl"/>
</geometry>
</collision>
<visual>
<origin xyz="-0.13214254961996313442 -0.010002240538597106934 -0.044999999999999984457" rpy="1.570796326794896558 7.9527313664624382197e-19 1.509022108463062819e-18" />
<geometry>
<mesh filename="package:///part_6.stl"/>
</geometry>
<material name="part_6_material">
<color rgba="0.91764705882352937127 0.91764705882352937127 0.91764705882352937127 1.0"/>
</material>
</visual>
<collision>
<origin xyz="-0.13214254961996313442 -0.010002240538597106934 -0.044999999999999984457" rpy="1.570796326794896558 7.9527313664624382197e-19 1.509022108463062819e-18" />
<geometry>
<mesh filename="package:///part_6.stl"/>
</geometry>
</collision>
<visual>
<origin xyz="-0.3039002607786561172 -0.0100022405385970653 0.1534999999999999698" rpy="1.570796326794896558 -5.8991832642835497686e-16 -8.7264319433343140139e-17" />
<geometry>
<mesh filename="package:///mg995_v3.stl"/>
</geometry>
<material name="mg995_v3_material">
<color rgba="0.62745098039215685404 0.62745098039215685404 0.62745098039215685404 1.0"/>
</material>
</visual>
<collision>
<origin xyz="-0.3039002607786561172 -0.0100022405385970653 0.1534999999999999698" rpy="1.570796326794896558 -5.8991832642835497686e-16 -8.7264319433343140139e-17" />
<geometry>
<mesh filename="package:///mg995_v3.stl"/>
</geometry>
</collision>
<inertial>
<origin xyz="-0.063706673597089619188 -3.849847845382690959e-06 -0.025894328139315470061" rpy="0 0 0"/>
<mass value="0.084196217898659775347" />
<inertia ixx="2.7955415541966263405e-05" ixy="-1.3492807390213130132e-08"  ixz="-6.0083029559706253844e-07" iyy="0.00010348466964737619285" iyz="-2.2291674578640644824e-09" izz="9.2987564203425945343e-05" />
</inertial>
</link>

<link name="gg_leg_tip_2">
<visual>
<origin xyz="-0.13214254961996318993 -0.010002240538597093056 -0.045000000000000067724" rpy="1.570796326794896558 -4.3153419525833209395e-17 2.1733365219964300396e-18" />
<geometry>
<mesh filename="package:///part_6.stl"/>
</geometry>
<material name="part_6_material">
<color rgba="0.91764705882352937127 0.91764705882352937127 0.91764705882352937127 1.0"/>
</material>
</visual>
<collision>
<origin xyz="-0.13214254961996318993 -0.010002240538597093056 -0.045000000000000067724" rpy="1.570796326794896558 -4.3153419525833209395e-17 2.1733365219964300396e-18" />
<geometry>
<mesh filename="package:///part_6.stl"/>
</geometry>
</collision>
<visual>
<origin xyz="-0.12259449000000011143 0.0098031712025948708478 -0.025281761415826456418" rpy="-1.5707963267948863439 1.570796326794896558 0" />
<geometry>
<mesh filename="package:///led_3mm_trans.stl"/>
</geometry>
<material name="led_3mm_trans_material">
<color rgba="1 1 1 1.0"/>
</material>
</visual>
<collision>
<origin xyz="-0.12259449000000011143 0.0098031712025948708478 -0.025281761415826456418" rpy="-1.5707963267948863439 1.570796326794896558 0" />
<geometry>
<mesh filename="package:///led_3mm_trans.stl"/>
</geometry>
</collision>
<visual>
<origin xyz="-0.12029449000000014269 0.01086547271180529628 -0.024348211468834188298" rpy="3.1415926535897895633 1.1537593169055811409e-16 -1.5707963267949043296" />
<geometry>
<mesh filename="package:///pulsador.stl"/>
</geometry>
<material name="pulsador_material">
<color rgba="1 0 0 1.0"/>
</material>
</visual>
<collision>
<origin xyz="-0.12029449000000014269 0.01086547271180529628 -0.024348211468834188298" rpy="3.1415926535897895633 1.1537593169055811409e-16 -1.5707963267949043296" />
<geometry>
<mesh filename="package:///pulsador.stl"/>
</geometry>
</collision>
<visual>
<origin xyz="-0.0264944900000001482 0.14717946631849004868 -0.050978735407716857519" rpy="-3.141592653589793116 1.5855429739971617877e-16 1.570796326794896336" />
<geometry>
<mesh filename="package:///part_25.stl"/>
</geometry>
<material name="part_25_material">
<color rgba="0.30196078431372547213 0.29019607843137257275 0.26274509803921569651 1.0"/>
</material>
</visual>
<collision>
<origin xyz="-0.0264944900000001482 0.14717946631849004868 -0.050978735407716857519" rpy="-3.141592653589793116 1.5855429739971617877e-16 1.570796326794896336" />
<geometry>
<mesh filename="package:///part_25.stl"/>
</geometry>
</collision>
<inertial>
<origin xyz="-0.058600447713097844615 0.00030798747790677233338 -0.025499135322571499923" rpy="0 0 0"/>
<mass value="0.15555503524263536441" />
<inertia ixx="4.2100962384746039194e-05" ixy="5.2877209940367713177e-06"  ixz="2.0615243018224348303e-07" iyy="0.00015940278081236450183" iyz="2.8650165663753474954e-08" izz="0.00015063387305898028718" />
</inertial>
</link>

<joint name="lb4" type="revolute">
<origin xyz="-0.09390026062964434983 -2.2405385970841740217e-06 -5.5511151231257827021e-17" rpy="-2.0024130311035016055e-15 -3.302822706616368304e-15 0.015414881823734714189" />
<parent link="gg_leg_middle_4" />
<child link="gg_leg_tip_2" />
<axis xyz="0 0 1"/>
<limit effort="1" velocity="20" />
<joint_properties friction="0.0"/>
</joint>

<joint name="lb3" type="revolute">
<origin xyz="-0.093900260629644516364 -2.2405385970980518096e-06 5.5511151231257827021e-17" rpy="1.4650501739147691609e-15 3.2128922540296999219e-15 0.012411801330701736912" />
<parent link="gg_leg_middle_3" />
<child link="gg_leg_middle_4" />
<axis xyz="0 0 1"/>
<limit effort="1" velocity="20" />
<joint_properties friction="0.0"/>
</joint>

<joint name="lb2" type="revolute">
<origin xyz="-0.093900260629644377586 0.025500000000000036526 -0.025497759461402910719" rpy="-1.570796326794896558 -0.025513752334984006465 -6.1092516534406132112e-16" />
<parent link="gg_leg_base_2" />
<child link="gg_leg_middle_3" />
<axis xyz="0 0 1"/>
<limit effort="1" velocity="20" />
<joint_properties friction="0.0"/>
</joint>

<joint name="lb1" type="revolute">
<origin xyz="-0.11817449693791860776 0.2353008040351553809 -0.071546722533612189254" rpy="0.070728748316633699433 0.01284629395373647863 -0.62271821568056084928" />
<parent link="gg_head" />
<child link="gg_leg_base_2" />
<axis xyz="0 0 1"/>
<limit effort="1" velocity="20" />
<joint_properties friction="0.0"/>
</joint>

<link name="gg_leg_base_3">
<visual>
<origin xyz="-0.30299741173027971985 -0.21949999999999975087 -0.015497759461402901837" rpy="-6.4638395122726746149e-17 -7.2378266972726020342e-17 -2.0780710418317661052e-16" />
<geometry>
<mesh filename="package:///part_11.stl"/>
</geometry>
<material name="part_11_material">
<color rgba="0.49803921568627451677 0.49803921568627451677 0.49803921568627451677 1.0"/>
</material>
</visual>
<collision>
<origin xyz="-0.30299741173027971985 -0.21949999999999975087 -0.015497759461402901837" rpy="-6.4638395122726746149e-17 -7.2378266972726020342e-17 -2.0780710418317661052e-16" />
<geometry>
<mesh filename="package:///part_11.stl"/>
</geometry>
</collision>
<visual>
<origin xyz="-0.13214254961996321769 -0.010002240538597106934 -0.044999999999999984457" rpy="1.570796326794896558 -3.3835675351690499587e-18 1.609055007351385903e-18" />
<geometry>
<mesh filename="package:///part_6.stl"/>
</geometry>
<material name="part_6_material">
<color rgba="0.91764705882352937127 0.91764705882352937127 0.91764705882352937127 1.0"/>
</material>
</visual>
<collision>
<origin xyz="-0.13214254961996321769 -0.010002240538597106934 -0.044999999999999984457" rpy="1.570796326794896558 -3.3835675351690499587e-18 1.609055007351385903e-18" />
<geometry>
<mesh filename="package:///part_6.stl"/>
</geometry>
</collision>
<visual>
<origin xyz="-0.30390026077865572862 0.17899999999999993694 -0.015497759461402887959" rpy="-5.4230054266865915909e-17 7.9883159311717776855e-17 -2.5166057248526272394e-16" />
<geometry>
<mesh filename="package:///mg995_v3.stl"/>
</geometry>
<material name="mg995_v3_material">
<color rgba="0.62745098039215685404 0.62745098039215685404 0.62745098039215685404 1.0"/>
</material>
</visual>
<collision>
<origin xyz="-0.30390026077865572862 0.17899999999999993694 -0.015497759461402887959" rpy="-5.4230054266865915909e-17 7.9883159311717776855e-17 -2.5166057248526272394e-16" />
<geometry>
<mesh filename="package:///mg995_v3.stl"/>
</geometry>
</collision>
<inertial>
<origin xyz="-0.063706673597089633065 -0.00036253314902454461012 -0.02552794514244558291" rpy="0 0 0"/>
<mass value="0.084196217898659775347" />
<inertia ixx="2.7957377169670417959e-05" ixy="-7.7137426145833297179e-07"  ixz="1.8403677325145866369e-07" iyy="9.7805049098282706974e-05" iyz="3.209981309960934697e-09" izz="9.8669146380223358766e-05" />
</inertial>
</link>

<link name="gg_leg_middle_5">
<visual>
<origin xyz="-0.30299741173027983088 -0.0100022405385970653 -0.24500000000000002331" rpy="1.570796326794896558 -8.9924838357723525975e-17 -1.8814674885660437416e-16" />
<geometry>
<mesh filename="package:///part_11.stl"/>
</geometry>
<material name="part_11_material">
<color rgba="0.49803921568627451677 0.49803921568627451677 0.49803921568627451677 1.0"/>
</material>
</visual>
<collision>
<origin xyz="-0.30299741173027983088 -0.0100022405385970653 -0.24500000000000002331" rpy="1.570796326794896558 -8.9924838357723525975e-17 -1.8814674885660437416e-16" />
<geometry>
<mesh filename="package:///part_11.stl"/>
</geometry>
</collision>
<visual>
<origin xyz="-0.13214254961996318993 -0.010002240538597106934 -0.045000000000000012212" rpy="1.570796326794896558 1.8541466803273086525e-17 5.9652859772316123315e-18" />
<geometry>
<mesh filename="package:///part_6.stl"/>
</geometry>
<material name="part_6_material">
<color rgba="0.91764705882352937127 0.91764705882352937127 0.91764705882352937127 1.0"/>
</material>
</visual>
<collision>
<origin xyz="-0.13214254961996318993 -0.010002240538597106934 -0.045000000000000012212" rpy="1.570796326794896558 1.8541466803273086525e-17 5.9652859772316123315e-18" />
<geometry>
<mesh filename="package:///part_6.stl"/>
</geometry>
</collision>
<visual>
<origin xyz="-0.30390026077865606169 -0.010002240538597051422 0.15350000000000002531" rpy="1.570796326794896558 -9.0655123301014681582e-17 -1.3268616747550837582e-16" />
<geometry>
<mesh filename="package:///mg995_v3.stl"/>
</geometry>
<material name="mg995_v3_material">
<color rgba="0.62745098039215685404 0.62745098039215685404 0.62745098039215685404 1.0"/>
</material>
</visual>
<collision>
<origin xyz="-0.30390026077865606169 -0.010002240538597051422 0.15350000000000002531" rpy="1.570796326794896558 -9.0655123301014681582e-17 -1.3268616747550837582e-16" />
<geometry>
<mesh filename="package:///mg995_v3.stl"/>
</geometry>
</collision>
<inertial>
<origin xyz="-0.063706673597089591432 -3.8498478453752590919e-06 -0.025894328139315515164" rpy="0 0 0"/>
<mass value="0.084196217898659775347" />
<inertia ixx="2.7955415541966263405e-05" ixy="-1.3492807390204590319e-08"  ixz="-6.0083029559704358608e-07" iyy="0.00010348466964737626061" iyz="-2.2291674578636757075e-09" izz="9.2987564203425986001e-05" />
</inertial>
</link>

<link name="gg_leg_middle_6">
<visual>
<origin xyz="-0.30299741173027999741 -0.010002240538596995911 -0.24500000000000027311" rpy="1.57079632679489678 -2.5695300966850715283e-16 -2.6314134047640244627e-16" />
<geometry>
<mesh filename="package:///part_11.stl"/>
</geometry>
<material name="part_11_material">
<color rgba="0.49803921568627451677 0.49803921568627451677 0.49803921568627451677 1.0"/>
</material>
</visual>
<collision>
<origin xyz="-0.30299741173027999741 -0.010002240538596995911 -0.24500000000000027311" rpy="1.57079632679489678 -2.5695300966850715283e-16 -2.6314134047640244627e-16" />
<geometry>
<mesh filename="package:///part_11.stl"/>
</geometry>
</collision>
<visual>
<origin xyz="-0.1321425496199630234 -0.010002240538597093056 -0.044999999999999998335" rpy="1.570796326794896558 4.7706137077192465069e-19 -4.9506110577816035241e-20" />
<geometry>
<mesh filename="package:///part_6.stl"/>
</geometry>
<material name="part_6_material">
<color rgba="0.91764705882352937127 0.91764705882352937127 0.91764705882352937127 1.0"/>
</material>
</visual>
<collision>
<origin xyz="-0.1321425496199630234 -0.010002240538597093056 -0.044999999999999998335" rpy="1.570796326794896558 4.7706137077192465069e-19 -4.9506110577816035241e-20" />
<geometry>
<mesh filename="package:///part_6.stl"/>
</geometry>
</collision>
<visual>
<origin xyz="-0.30390026077865600618 -0.010002240538597023667 0.15350000000000002531" rpy="1.57079632679489678 4.32291149244204998e-16 -3.3221997328936598092e-16" />
<geometry>
<mesh filename="package:///mg995_v3.stl"/>
</geometry>
<material name="mg995_v3_material">
<color rgba="0.62745098039215685404 0.62745098039215685404 0.62745098039215685404 1.0"/>
</material>
</visual>
<collision>
<origin xyz="-0.30390026077865600618 -0.010002240538597023667 0.15350000000000002531" rpy="1.57079632679489678 4.32291149244204998e-16 -3.3221997328936598092e-16" />
<geometry>
<mesh filename="package:///mg995_v3.stl"/>
</geometry>
</collision>
<inertial>
<origin xyz="-0.063706673597089633065 -3.8498478453643670953e-06 -0.02589432813931559843" rpy="0 0 0"/>
<mass value="0.084196217898659775347" />
<inertia ixx="2.7955415541966270181e-05" ixy="-1.3492807390191603584e-08"  ixz="-6.0083029559719404031e-07" iyy="0.00010348466964737654521" iyz="-2.2291674578620019076e-09" izz="9.2987564203426324814e-05" />
</inertial>
</link>

<link name="gg_leg_tip_3">
<visual>
<origin xyz="-0.13214254961996318993 -0.010002240538597106934 -0.044999999999999970579" rpy="1.570796326794896558 3.1471811077026669864e-17 -2.0529191600312144776e-18" />
<geometry>
<mesh filename="package:///part_6.stl"/>
</geometry>
<material name="part_6_material">
<color rgba="0.91764705882352937127 0.91764705882352937127 0.91764705882352937127 1.0"/>
</material>
</visual>
<collision>
<origin xyz="-0.13214254961996318993 -0.010002240538597106934 -0.044999999999999970579" rpy="1.570796326794896558 3.1471811077026669864e-17 -2.0529191600312144776e-18" />
<geometry>
<mesh filename="package:///part_6.stl"/>
</geometry>
</collision>
<visual>
<origin xyz="-0.12259449000000011143 0.0098031712025948708478 -0.025281761415826359274" rpy="-1.5707963267948863439 1.570796326794896558 0" />
<geometry>
<mesh filename="package:///led_3mm_trans.stl"/>
</geometry>
<material name="led_3mm_trans_material">
<color rgba="1 1 1 1.0"/>
</material>
</visual>
<collision>
<origin xyz="-0.12259449000000011143 0.0098031712025948708478 -0.025281761415826359274" rpy="-1.5707963267948863439 1.570796326794896558 0" />
<geometry>
<mesh filename="package:///led_3mm_trans.stl"/>
</geometry>
</collision>
<visual>
<origin xyz="-0.12029449000000014269 0.01086547271180529628 -0.024348211468834091153" rpy="3.1415926535897891192 1.4521439264736081443e-16 -1.5707963267949043296" />
<geometry>
<mesh filename="package:///pulsador.stl"/>
</geometry>
<material name="pulsador_material">
<color rgba="1 0 0 1.0"/>
</material>
</visual>
<collision>
<origin xyz="-0.12029449000000014269 0.01086547271180529628 -0.024348211468834091153" rpy="3.1415926535897891192 1.4521439264736081443e-16 -1.5707963267949043296" />
<geometry>
<mesh filename="package:///pulsador.stl"/>
</geometry>
</collision>
<visual>
<origin xyz="-0.026494490000000037178 0.14717946631848999317 -0.050978735407716732619" rpy="-3.1415926535897926719 2.0346502602397741155e-16 1.570796326794896558" />
<geometry>
<mesh filename="package:///part_25.stl"/>
</geometry>
<material name="part_25_material">
<color rgba="0.30196078431372547213 0.29019607843137257275 0.26274509803921569651 1.0"/>
</material>
</visual>
<collision>
<origin xyz="-0.026494490000000037178 0.14717946631848999317 -0.050978735407716732619" rpy="-3.1415926535897926719 2.0346502602397741155e-16 1.570796326794896558" />
<geometry>
<mesh filename="package:///part_25.stl"/>
</geometry>
</collision>
<inertial>
<origin xyz="-0.058600447713097768287 0.00030798747790674593306 -0.025499135322571364615" rpy="0 0 0"/>
<mass value="0.15555503524263536441" />
<inertia ixx="4.2100962384746079851e-05" ixy="5.2877209940367620003e-06"  ixz="2.0615243018221537212e-07" iyy="0.0001594027808123643121" iyz="2.8650165663768185534e-08" izz="0.00015063387305898015165" />
</inertial>
</link>

<joint name="rb4" type="revolute">
<origin xyz="-0.093900260629640575072 -2.240538596556818085e-06 3.233524559220768424e-15" rpy="6.4962079859848688506e-16 1.1884826473081579551e-15 -0.083693820133456484078" />
<parent link="gg_leg_middle_6" />
<child link="gg_leg_tip_3" />
<axis xyz="0 0 1"/>
<limit effort="1" velocity="20" />
<joint_properties friction="0.0"/>
</joint>

<joint name="rb3" type="revolute">
<origin xyz="-0.093900260629644460852 -2.2405385971258073852e-06 -1.3877787807814456755e-17" rpy="-1.0953516697685908435e-15 -1.1239017013348206417e-14 0.028657401914974022644" />
<parent link="gg_leg_middle_5" />
<child link="gg_leg_middle_6" />
<axis xyz="0 0 1"/>
<limit effort="1" velocity="20" />
<joint_properties friction="0.0"/>
</joint>

<joint name="rb2" type="revolute">
<origin xyz="-0.093900260629644377586 0.025500000000000050404 -0.025497759461402896841" rpy="-1.570796326794896558 -0.030060779457612516602 -1.1785218828605868652e-14" />
<parent link="gg_leg_base_3" />
<child link="gg_leg_middle_5" />
<axis xyz="0 0 1"/>
<limit effort="1" velocity="20" />
<joint_properties friction="0.0"/>
</joint>

<joint name="rb1" type="revolute">
<origin xyz="0.04087497650436404395 0.26150142787351615681 -0.064929590909858711512" rpy="-0.013188942176199274295 0.070665757445816726467 -2.198819767452965479" />
<parent link="gg_head" />
<child link="gg_leg_base_3" />
<axis xyz="0 0 1"/>
<limit effort="1" velocity="20" />
<joint_properties friction="0.0"/>
</joint>

<link name="gg_leg_base_4">
<visual>
<origin xyz="-0.30299741173027949781 -0.21949999999999947331 -0.015497759461402957348" rpy="2.5976325127278665243e-16 5.4316366484344125018e-17 9.5021173493489809076e-17" />
<geometry>
<mesh filename="package:///part_11.stl"/>
</geometry>
<material name="part_11_material">
<color rgba="0.49803921568627451677 0.49803921568627451677 0.49803921568627451677 1.0"/>
</material>
</visual>
<collision>
<origin xyz="-0.30299741173027949781 -0.21949999999999947331 -0.015497759461402957348" rpy="2.5976325127278665243e-16 5.4316366484344125018e-17 9.5021173493489809076e-17" />
<geometry>
<mesh filename="package:///part_11.stl"/>
</geometry>
</collision>
<visual>
<origin xyz="-0.13214254961996316218 -0.010002240538597106934 -0.04500000000000002609" rpy="1.570796326794896558 -1.2306247106879059156e-18 7.354960678563289461e-18" />
<geometry>
<mesh filename="package:///part_6.stl"/>
</geometry>
<material name="part_6_material">
<color rgba="0.91764705882352937127 0.91764705882352937127 0.91764705882352937127 1.0"/>
</material>
</visual>
<collision>
<origin xyz="-0.13214254961996316218 -0.010002240538597106934 -0.04500000000000002609" rpy="1.570796326794896558 -1.2306247106879059156e-18 7.354960678563289461e-18" />
<geometry>
<mesh filename="package:///part_6.stl"/>
</geometry>
</collision>
<visual>
<origin xyz="-0.30390026077865528453 0.17899999999999963163 -0.015497759461402901837" rpy="1.4902766852046383929e-16 -7.9186388681764368321e-18 9.1494109341127528898e-17" />
<geometry>
<mesh filename="package:///mg995_v3.stl"/>
</geometry>
<material name="mg995_v3_material">
<color rgba="0.62745098039215685404 0.62745098039215685404 0.62745098039215685404 1.0"/>
</material>
</visual>
<collision>
<origin xyz="-0.30390026077865528453 0.17899999999999963163 -0.015497759461402901837" rpy="1.4902766852046383929e-16 -7.9186388681764368321e-18 9.1494109341127528898e-17" />
<geometry>
<mesh filename="package:///mg995_v3.stl"/>
</geometry>
</collision>
<inertial>
<origin xyz="-0.063706673597089466532 -0.00036253314902451148774 -0.025527945142445621074" rpy="0 0 0"/>
<mass value="0.084196217898659775347" />
<inertia ixx="2.795737716967038069e-05" ixy="-7.713742614583115842e-07"  ixz="1.8403677325145906073e-07" iyy="9.7805049098282341056e-05" iyz="3.2099813099657621231e-09" izz="9.8669146380223060611e-05" />
</inertial>
</link>

<link name="gg_leg_middle_7">
<visual>
<origin xyz="-0.30299741173028010843 -0.010002240538597079178 -0.24499999999999974576" rpy="1.5707963267948970021 1.1243331007550896748e-15 1.8043698899767636997e-16" />
<geometry>
<mesh filename="package:///part_11.stl"/>
</geometry>
<material name="part_11_material">
<color rgba="0.49803921568627451677 0.49803921568627451677 0.49803921568627451677 1.0"/>
</material>
</visual>
<collision>
<origin xyz="-0.30299741173028010843 -0.010002240538597079178 -0.24499999999999974576" rpy="1.5707963267948970021 1.1243331007550896748e-15 1.8043698899767636997e-16" />
<geometry>
<mesh filename="package:///part_11.stl"/>
</geometry>
</collision>
<visual>
<origin xyz="-0.13214254961996318993 -0.010002240538597093056 -0.045000000000000012212" rpy="1.570796326794896558 1.4444681004092015556e-17 -6.6474268037837193489e-18" />
<geometry>
<mesh filename="package:///part_6.stl"/>
</geometry>
<material name="part_6_material">
<color rgba="0.91764705882352937127 0.91764705882352937127 0.91764705882352937127 1.0"/>
</material>
</visual>
<collision>
<origin xyz="-0.13214254961996318993 -0.010002240538597093056 -0.045000000000000012212" rpy="1.570796326794896558 1.4444681004092015556e-17 -6.6474268037837193489e-18" />
<geometry>
<mesh filename="package:///part_6.stl"/>
</geometry>
</collision>
<visual>
<origin xyz="-0.30390026077865600618 -0.010002240538597106934 0.1534999999999999698" rpy="1.57079632679489678 -3.4148195788395252772e-16 7.1678387442577771432e-18" />
<geometry>
<mesh filename="package:///mg995_v3.stl"/>
</geometry>
<material name="mg995_v3_material">
<color rgba="0.62745098039215685404 0.62745098039215685404 0.62745098039215685404 1.0"/>
</material>
</visual>
<collision>
<origin xyz="-0.30390026077865600618 -0.010002240538597106934 0.1534999999999999698" rpy="1.57079632679489678 -3.4148195788395252772e-16 7.1678387442577771432e-18" />
<geometry>
<mesh filename="package:///mg995_v3.stl"/>
</geometry>
</collision>
<inertial>
<origin xyz="-0.063706673597089549799 -3.8498478453796187705e-06 -0.025894328139315515164" rpy="0 0 0"/>
<mass value="0.084196217898659775347" />
<inertia ixx="2.7955415541966266793e-05" ixy="-1.3492807390221064448e-08"  ixz="-6.0083029559710774882e-07" iyy="0.00010348466964737611153" iyz="-2.2291674578628257795e-09" izz="9.2987564203425864028e-05" />
</inertial>
</link>

<link name="gg_leg_middle_8">
<visual>
<origin xyz="-0.30299741173027988639 -0.010002240538597079178 -0.24499999999999999556" rpy="1.570796326794896558 -2.5836205279651659624e-17 -2.2906487458298079003e-16" />
<geometry>
<mesh filename="package:///part_11.stl"/>
</geometry>
<material name="part_11_material">
<color rgba="0.49803921568627451677 0.49803921568627451677 0.49803921568627451677 1.0"/>
</material>
</visual>
<collision>
<origin xyz="-0.30299741173027988639 -0.010002240538597079178 -0.24499999999999999556" rpy="1.570796326794896558 -2.5836205279651659624e-17 -2.2906487458298079003e-16" />
<geometry>
<mesh filename="package:///part_11.stl"/>
</geometry>
</collision>
<visual>
<origin xyz="-0.13214254961996324544 -0.010002240538597106934 -0.044999999999999998335" rpy="1.570796326794896558 -1.1822942760263817636e-17 -7.5253197502121468811e-18" />
<geometry>
<mesh filename="package:///part_6.stl"/>
</geometry>
<material name="part_6_material">
<color rgba="0.91764705882352937127 0.91764705882352937127 0.91764705882352937127 1.0"/>
</material>
</visual>
<collision>
<origin xyz="-0.13214254961996324544 -0.010002240538597106934 -0.044999999999999998335" rpy="1.570796326794896558 -1.1822942760263817636e-17 -7.5253197502121468811e-18" />
<geometry>
<mesh filename="package:///part_6.stl"/>
</geometry>
</collision>
<visual>
<origin xyz="-0.30390026077865622822 -0.010002240538596843256 0.15350000000000008082" rpy="1.5707963267948961139 -1.1366360577384756364e-18 -6.3757577725204718236e-16" />
<geometry>
<mesh filename="package:///mg995_v3.stl"/>
</geometry>
<material name="mg995_v3_material">
<color rgba="0.62745098039215685404 0.62745098039215685404 0.62745098039215685404 1.0"/>
</material>
</visual>
<collision>
<origin xyz="-0.30390026077865622822 -0.010002240538596843256 0.15350000000000008082" rpy="1.5707963267948961139 -1.1366360577384756364e-18 -6.3757577725204718236e-16" />
<geometry>
<mesh filename="package:///mg995_v3.stl"/>
</geometry>
</collision>
<inertial>
<origin xyz="-0.063706673597089619188 -3.8498478453803048672e-06 -0.025894328139315532511" rpy="0 0 0"/>
<mass value="0.084196217898659775347" />
<inertia ixx="2.7955415541966280345e-05" ixy="-1.3492807390195574051e-08"  ixz="-6.0083029559714004196e-07" iyy="0.0001034846696473762064" iyz="-2.2291674578646364778e-09" izz="9.2987564203425958896e-05" />
</inertial>
</link>

<link name="gg_leg_tip_4">
<visual>
<origin xyz="-0.13214254961996324544 -0.010002240538597106934 -0.044999999999999970579" rpy="1.570796326794896558 -8.532504197931484297e-19 1.9695420351863858135e-18" />
<geometry>
<mesh filename="package:///part_6.stl"/>
</geometry>
<material name="part_6_material">
<color rgba="0.91764705882352937127 0.91764705882352937127 0.91764705882352937127 1.0"/>
</material>
</visual>
<collision>
<origin xyz="-0.13214254961996324544 -0.010002240538597106934 -0.044999999999999970579" rpy="1.570796326794896558 -8.532504197931484297e-19 1.9695420351863858135e-18" />
<geometry>
<mesh filename="package:///part_6.stl"/>
</geometry>
</collision>
<visual>
<origin xyz="-0.12259448999999983387 0.0098031712025949124811 -0.025281761415826373152" rpy="-1.5707963267948854558 1.570796326794896336 0" />
<geometry>
<mesh filename="package:///led_3mm_trans.stl"/>
</geometry>
<material name="led_3mm_trans_material">
<color rgba="1 1 1 1.0"/>
</material>
</visual>
<collision>
<origin xyz="-0.12259448999999983387 0.0098031712025949124811 -0.025281761415826373152" rpy="-1.5707963267948854558 1.570796326794896336 0" />
<geometry>
<mesh filename="package:///led_3mm_trans.stl"/>
</geometry>
</collision>
<visual>
<origin xyz="-0.12029449000000008718 0.010865472711805365669 -0.024348211468834077276" rpy="3.1415926535897891192 -8.2047033526659414979e-17 -1.5707963267949041075" />
<geometry>
<mesh filename="package:///pulsador.stl"/>
</geometry>
<material name="pulsador_material">
<color rgba="1 0 0 1.0"/>
</material>
</visual>
<collision>
<origin xyz="-0.12029449000000008718 0.010865472711805365669 -0.024348211468834077276" rpy="3.1415926535897891192 -8.2047033526659414979e-17 -1.5707963267949041075" />
<geometry>
<mesh filename="package:///pulsador.stl"/>
</geometry>
</collision>
<visual>
<origin xyz="-0.0264944900000001482 0.14717946631849004868 -0.050978735407716746497" rpy="-3.1415926535897926719 1.048693881375033249e-16 1.5707963267948970021" />
<geometry>
<mesh filename="package:///part_25.stl"/>
</geometry>
<material name="part_25_material">
<color rgba="0.30196078431372547213 0.29019607843137257275 0.26274509803921569651 1.0"/>
</material>
</visual>
<collision>
<origin xyz="-0.0264944900000001482 0.14717946631849004868 -0.050978735407716746497" rpy="-3.1415926535897926719 1.048693881375033249e-16 1.5707963267948970021" />
<geometry>
<mesh filename="package:///part_25.stl"/>
</geometry>
</collision>
<inertial>
<origin xyz="-0.05860044771309775441 0.00030798747790681987565 -0.025499135322571388901" rpy="0 0 0"/>
<mass value="0.15555503524263536441" />
<inertia ixx="4.2100962384745957878e-05" ixy="5.2877209940367416715e-06"  ixz="2.0615243018219986083e-07" iyy="0.00015940278081236414947" iyz="2.8650165663763798168e-08" izz="0.00015063387305897998902" />
</inertial>
</link>

<joint name="rm4" type="revolute">
<origin xyz="-0.093900260629643517163 -2.2405385970702962339e-06 8.3266726846886740532e-17" rpy="-2.4114463600947789087e-15 -7.9985792070857155392e-16 -0.025122084517565274747" />
<parent link="gg_leg_middle_8" />
<child link="gg_leg_tip_4" />
<axis xyz="0 0 1"/>
<limit effort="1" velocity="20" />
<joint_properties friction="0.0"/>
</joint>

<joint name="rm3" type="revolute">
<origin xyz="-0.093900260629644460852 -2.2405385970980518096e-06 1.3877787807814456755e-17" rpy="1.3423836784922137271e-15 4.2021217730199230472e-15 0.00064427834614642117816" />
<parent link="gg_leg_middle_7" />
<child link="gg_leg_middle_8" />
<axis xyz="0 0 1"/>
<limit effort="1" velocity="20" />
<joint_properties friction="0.0"/>
</joint>

<joint name="rm2" type="revolute">
<origin xyz="-0.093900260629644377586 0.025499999999999925504 -0.025497759461402924597" rpy="-1.570796326794896558 -0.0086691555026288547731 2.6601492505377240611e-15" />
<parent link="gg_leg_base_4" />
<child link="gg_leg_middle_7" />
<axis xyz="0 0 1"/>
<limit effort="1" velocity="20" />
<joint_properties friction="0.0"/>
</joint>

<joint name="rm1" type="revolute">
<origin xyz="0.1434033125541158693 0.13704002152471553289 -0.069858359443739859174" rpy="-0.058068403123315306957 0.042395628432127505092 -2.9549764894743910659" />
<parent link="gg_head" />
<child link="gg_leg_base_4" />
<axis xyz="0 0 1"/>
<limit effort="1" velocity="20" />
<joint_properties friction="0.0"/>
</joint>

<link name="gg_leg_base_5">
<visual>
<origin xyz="-0.30299741173027971985 -0.21949999999999972311 -0.015497759461402943471" rpy="2.1217403659735662502e-16 4.1399429654960057219e-17 4.5822192802426524992e-16" />
<geometry>
<mesh filename="package:///part_11.stl"/>
</geometry>
<material name="part_11_material">
<color rgba="0.49803921568627451677 0.49803921568627451677 0.49803921568627451677 1.0"/>
</material>
</visual>
<collision>
<origin xyz="-0.30299741173027971985 -0.21949999999999972311 -0.015497759461402943471" rpy="2.1217403659735662502e-16 4.1399429654960057219e-17 4.5822192802426524992e-16" />
<geometry>
<mesh filename="package:///part_11.stl"/>
</geometry>
</collision>
<visual>
<origin xyz="-0.13214254961996313442 -0.010002240538597099995 -0.045000000000000012212" rpy="1.570796326794896558 5.1852764420918059337e-18 -8.2613493944888986343e-17" />
<geometry>
<mesh filename="package:///part_6.stl"/>
</geometry>
<material name="part_6_material">
<color rgba="0.91764705882352937127 0.91764705882352937127 0.91764705882352937127 1.0"/>
</material>
</visual>
<collision>
<origin xyz="-0.13214254961996313442 -0.010002240538597099995 -0.045000000000000012212" rpy="1.570796326794896558 5.1852764420918059337e-18 -8.2613493944888986343e-17" />
<geometry>
<mesh filename="package:///part_6.stl"/>
</geometry>
</collision>
<visual>
<origin xyz="-0.30390026077865567311 0.17899999999999960387 -0.015497759461402860204" rpy="-7.8542708091264507144e-17 2.1791114463930515031e-16 2.1315457349206071394e-16" />
<geometry>
<mesh filename="package:///mg995_v3.stl"/>
</geometry>
<material name="mg995_v3_material">
<color rgba="0.62745098039215685404 0.62745098039215685404 0.62745098039215685404 1.0"/>
</material>
</visual>
<collision>
<origin xyz="-0.30390026077865567311 0.17899999999999960387 -0.015497759461402860204" rpy="-7.8542708091264507144e-17 2.1791114463930515031e-16 2.1315457349206071394e-16" />
<geometry>
<mesh filename="package:///mg995_v3.stl"/>
</geometry>
</collision>
<inertial>
<origin xyz="-0.063706673597089549799 -0.00036253314902456152367 -0.025527945142445589849" rpy="0 0 0"/>
<mass value="0.084196217898659775347" />
<inertia ixx="2.7957377169670411183e-05" ixy="-7.7137426145832810135e-07"  ixz="1.8403677325147346029e-07" iyy="9.7805049098282652764e-05" iyz="3.2099813099658994351e-09" izz="9.8669146380223331661e-05" />
</inertial>
</link>

<link name="gg_leg_middle_9">
<visual>
<origin xyz="-0.30299741173027999741 -0.010002240538597245711 -0.24499999999999977351" rpy="1.57079632679489678 5.4092884606249378434e-16 5.9731591658570444873e-16" />
<geometry>
<mesh filename="package:///part_11.stl"/>
</geometry>
<material name="part_11_material">
<color rgba="0.49803921568627451677 0.49803921568627451677 0.49803921568627451677 1.0"/>
</material>
</visual>
<collision>
<origin xyz="-0.30299741173027999741 -0.010002240538597245711 -0.24499999999999977351" rpy="1.57079632679489678 5.4092884606249378434e-16 5.9731591658570444873e-16" />
<geometry>
<mesh filename="package:///part_11.stl"/>
</geometry>
</collision>
<visual>
<origin xyz="-0.13214254961996318993 -0.010002240538597106934 -0.044999999999999984457" rpy="1.570796326794896558 -9.7184222214982869322e-18 -3.192748364533779506e-18" />
<geometry>
<mesh filename="package:///part_6.stl"/>
</geometry>
<material name="part_6_material">
<color rgba="0.91764705882352937127 0.91764705882352937127 0.91764705882352937127 1.0"/>
</material>
</visual>
<collision>
<origin xyz="-0.13214254961996318993 -0.010002240538597106934 -0.044999999999999984457" rpy="1.570796326794896558 -9.7184222214982869322e-18 -3.192748364533779506e-18" />
<geometry>
<mesh filename="package:///part_6.stl"/>
</geometry>
</collision>
<visual>
<origin xyz="-0.30390026077865617271 -0.010002240538597217956 0.15350000000000002531" rpy="1.57079632679489678 -3.3033282894687416127e-17 3.2554948572541679522e-16" />
<geometry>
<mesh filename="package:///mg995_v3.stl"/>
</geometry>
<material name="mg995_v3_material">
<color rgba="0.62745098039215685404 0.62745098039215685404 0.62745098039215685404 1.0"/>
</material>
</visual>
<collision>
<origin xyz="-0.30390026077865617271 -0.010002240538597217956 0.15350000000000002531" rpy="1.57079632679489678 -3.3033282894687416127e-17 3.2554948572541679522e-16" />
<geometry>
<mesh filename="package:///mg995_v3.stl"/>
</geometry>
</collision>
<inertial>
<origin xyz="-0.063706673597089688577 -3.8498478453981848857e-06 -0.025894328139315532511" rpy="0 0 0"/>
<mass value="0.084196217898659775347" />
<inertia ixx="2.795541554196625324e-05" ixy="-1.3492807390238501416e-08"  ixz="-6.0083029559711071344e-07" iyy="0.00010348466964737638258" iyz="-2.2291674578615316554e-09" izz="9.2987564203426107973e-05" />
</inertial>
</link>

<link name="gg_leg_middle_10">
<visual>
<origin xyz="-0.30299741173027971985 -0.010002240538597093056 -0.24500000000000010658" rpy="1.570796326794896558 -3.5817374933595067092e-16 -1.0927008770254284296e-16" />
<geometry>
<mesh filename="package:///part_11.stl"/>
</geometry>
<material name="part_11_material">
<color rgba="0.49803921568627451677 0.49803921568627451677 0.49803921568627451677 1.0"/>
</material>
</visual>
<collision>
<origin xyz="-0.30299741173027971985 -0.010002240538597093056 -0.24500000000000010658" rpy="1.570796326794896558 -3.5817374933595067092e-16 -1.0927008770254284296e-16" />
<geometry>
<mesh filename="package:///part_11.stl"/>
</geometry>
</collision>
<visual>
<origin xyz="-0.13214254961996313442 -0.010002240538597120811 -0.045000000000000039968" rpy="1.570796326794896558 -7.9600179606602973761e-17 4.1055711333580864238e-18" />
<geometry>
<mesh filename="package:///part_6.stl"/>
</geometry>
<material name="part_6_material">
<color rgba="0.91764705882352937127 0.91764705882352937127 0.91764705882352937127 1.0"/>
</material>
</visual>
<collision>
<origin xyz="-0.13214254961996313442 -0.010002240538597120811 -0.045000000000000039968" rpy="1.570796326794896558 -7.9600179606602973761e-17 4.1055711333580864238e-18" />
<geometry>
<mesh filename="package:///part_6.stl"/>
</geometry>
</collision>
<visual>
<origin xyz="-0.30390026077865595067 -0.010002240538597176323 0.1534999999999999698" rpy="1.57079632679489678 -8.4753990913307995618e-17 7.6781443418045752018e-17" />
<geometry>
<mesh filename="package:///mg995_v3.stl"/>
</geometry>
<material name="mg995_v3_material">
<color rgba="0.62745098039215685404 0.62745098039215685404 0.62745098039215685404 1.0"/>
</material>
</visual>
<collision>
<origin xyz="-0.30390026077865595067 -0.010002240538597176323 0.1534999999999999698" rpy="1.57079632679489678 -8.4753990913307995618e-17 7.6781443418045752018e-17" />
<geometry>
<mesh filename="package:///mg995_v3.stl"/>
</geometry>
</collision>
<inertial>
<origin xyz="-0.063706673597089563676 -3.8498478454077326411e-06 -0.025894328139315577614" rpy="0 0 0"/>
<mass value="0.084196217898659775347" />
<inertia ixx="2.7955415541966246464e-05" ixy="-1.3492807390226343515e-08"  ixz="-6.0083029559708096141e-07" iyy="0.00010348466964737611153" iyz="-2.229167457862239722e-09" izz="9.2987564203425836923e-05" />
</inertial>
</link>

<link name="gg_leg_tip_5">
<visual>
<origin xyz="-0.13214254961996324544 -0.010002240538597093056 -0.044999999999999984457" rpy="1.570796326794896558 -8.1766089231038317571e-17 -6.2202501300788673771e-18" />
<geometry>
<mesh filename="package:///part_6.stl"/>
</geometry>
<material name="part_6_material">
<color rgba="0.91764705882352937127 0.91764705882352937127 0.91764705882352937127 1.0"/>
</material>
</visual>
<collision>
<origin xyz="-0.13214254961996324544 -0.010002240538597093056 -0.044999999999999984457" rpy="1.570796326794896558 -8.1766089231038317571e-17 -6.2202501300788673771e-18" />
<geometry>
<mesh filename="package:///part_6.stl"/>
</geometry>
</collision>
<visual>
<origin xyz="-0.12259449000000000041 0.0098031712025949124811 -0.025281761415826428663" rpy="-1.570796326794886566 1.570796326794896336 0" />
<geometry>
<mesh filename="package:///led_3mm_trans.stl"/>
</geometry>
<material name="led_3mm_trans_material">
<color rgba="1 1 1 1.0"/>
</material>
</visual>
<collision>
<origin xyz="-0.12259449000000000041 0.0098031712025949124811 -0.025281761415826428663" rpy="-1.570796326794886566 1.570796326794896336 0" />
<geometry>
<mesh filename="package:///led_3mm_trans.stl"/>
</geometry>
</collision>
<visual>
<origin xyz="-0.12029448999999997616 0.010865472711805351791 -0.024348211468834195237" rpy="3.1415926535897900074 -2.1739153986758564147e-16 -1.5707963267949043296" />
<geometry>
<mesh filename="package:///pulsador.stl"/>
</geometry>
<material name="pulsador_material">
<color rgba="1 0 0 1.0"/>
</material>
</visual>
<collision>
<origin xyz="-0.12029448999999997616 0.010865472711805351791 -0.024348211468834195237" rpy="3.1415926535897900074 -2.1739153986758564147e-16 -1.5707963267949043296" />
<geometry>
<mesh filename="package:///pulsador.stl"/>
</geometry>
</collision>
<visual>
<origin xyz="-0.026494489999999981666 0.14717946631849007644 -0.050978735407716753436" rpy="3.141592653589793116 5.8174348967149640368e-17 1.570796326794896336" />
<geometry>
<mesh filename="package:///part_25.stl"/>
</geometry>
<material name="part_25_material">
<color rgba="0.30196078431372547213 0.29019607843137257275 0.26274509803921569651 1.0"/>
</material>
</visual>
<collision>
<origin xyz="-0.026494489999999981666 0.14717946631849007644 -0.050978735407716753436" rpy="3.141592653589793116 5.8174348967149640368e-17 1.570796326794896336" />
<geometry>
<mesh filename="package:///part_25.stl"/>
</geometry>
</collision>
<inertial>
<origin xyz="-0.058600447713097747471 0.00030798747790679689056 -0.025499135322571434004" rpy="0 0 0"/>
<mass value="0.15555503524263536441" />
<inertia ixx="4.2100962384746052746e-05" ixy="5.2877209940367899524e-06"  ixz="2.0615243018215856797e-07" iyy="0.00015940278081236420368" iyz="2.86501656637134725e-08" izz="0.00015063387305897993481" />
</inertial>
</link>

<joint name="rf4" type="revolute">
<origin xyz="-0.09390026062965445286 -2.240538596556818085e-06 -3.7973096889132307297e-15" rpy="6.5700514527804111315e-16 -3.0505656096484096144e-15 -0.010706663521110104664" />
<parent link="gg_leg_middle_10" />
<child link="gg_leg_tip_5" />
<axis xyz="0 0 1"/>
<limit effort="1" velocity="20" />
<joint_properties friction="0.0"/>
</joint>

<joint name="rf3" type="revolute">
<origin xyz="-0.093900260629644516364 -2.2405385973478519901e-06 -6.2450045135165055399e-17" rpy="-9.8236355075384574011e-16 3.2142128908315931974e-15 -0.013620290587320288064" />
<parent link="gg_leg_middle_9" />
<child link="gg_leg_middle_10" />
<axis xyz="0 0 1"/>
<limit effort="1" velocity="20" />
<joint_properties friction="0.0"/>
</joint>

<joint name="rf2" type="revolute">
<origin xyz="-0.093900260629644266563 0.025500000000000022649 -0.025497759461402910719" rpy="-1.5707963267948954478 0.025880339654092785612 -1.2208060713298555304e-15" />
<parent link="gg_leg_base_5" />
<child link="gg_leg_middle_9" />
<axis xyz="0 0 1"/>
<limit effort="1" velocity="20" />
<joint_properties friction="0.0"/>
</joint>

<joint name="rf1" type="revolute">
<origin xyz="0.086882175161584890288 -0.013622008662446241645 -0.081404259601374651112" rpy="-0.070801988842103855126 -0.012435622148176646642 2.5246684821076574856" />
<parent link="gg_head" />
<child link="gg_leg_base_5" />
<axis xyz="0 0 1"/>
<limit effort="1" velocity="20" />
<joint_properties friction="0.0"/>
</joint>

<link name="gg_leg_base_6">
<visual>
<origin xyz="-0.30299741173027960883 -0.21949999999999980638 -0.015497759461402776937" rpy="3.6506517150238807476e-17 4.7405459406725100648e-16 -1.132238138930955939e-16" />
<geometry>
<mesh filename="package:///part_11.stl"/>
</geometry>
<material name="part_11_material">
<color rgba="0.49803921568627451677 0.49803921568627451677 0.49803921568627451677 1.0"/>
</material>
</visual>
<collision>
<origin xyz="-0.30299741173027960883 -0.21949999999999980638 -0.015497759461402776937" rpy="3.6506517150238807476e-17 4.7405459406725100648e-16 -1.132238138930955939e-16" />
<geometry>
<mesh filename="package:///part_11.stl"/>
</geometry>
</collision>
<visual>
<origin xyz="-0.13214254961996313442 -0.010002240538597099995 -0.045000000000000012212" rpy="1.570796326794896558 -1.0234380655289746237e-17 -3.8550073696775552794e-17" />
<geometry>
<mesh filename="package:///part_6.stl"/>
</geometry>
<material name="part_6_material">
<color rgba="0.91764705882352937127 0.91764705882352937127 0.91764705882352937127 1.0"/>
</material>
</visual>
<collision>
<origin xyz="-0.13214254961996313442 -0.010002240538597099995 -0.045000000000000012212" rpy="1.570796326794896558 -1.0234380655289746237e-17 -3.8550073696775552794e-17" />
<geometry>
<mesh filename="package:///part_6.stl"/>
</geometry>
</collision>
<visual>
<origin xyz="-0.30390026077865567311 0.17899999999999977041 -0.015497759461402846326" rpy="-1.7455630749854540925e-16 2.6635369647909793145e-16 -1.364916925819186357e-16" />
<geometry>
<mesh filename="package:///mg995_v3.stl"/>
</geometry>
<material name="mg995_v3_material">
<color rgba="0.62745098039215685404 0.62745098039215685404 0.62745098039215685404 1.0"/>
</material>
</visual>
<collision>
<origin xyz="-0.30390026077865567311 0.17899999999999977041 -0.015497759461402846326" rpy="-1.7455630749854540925e-16 2.6635369647909793145e-16 -1.364916925819186357e-16" />
<geometry>
<mesh filename="package:///mg995_v3.stl"/>
</geometry>
</collision>
<inertial>
<origin xyz="-0.063706673597089549799 -0.00036253314902455800002 -0.025527945142445575971" rpy="0 0 0"/>
<mass value="0.084196217898659775347" />
<inertia ixx="2.7957377169670414571e-05" ixy="-7.7137426145841979266e-07"  ixz="1.8403677325149916245e-07" iyy="9.7805049098282774737e-05" iyz="3.2099813099591128318e-09" izz="9.8669146380223399424e-05" />
</inertial>
</link>

<link name="gg_leg_middle_11">
<visual>
<origin xyz="-0.30299741173028005292 -0.010002240538597134689 -0.24499999999999966249" rpy="1.57079632679489678 1.1425778869832579519e-15 -1.1280364284126089603e-16" />
<geometry>
<mesh filename="package:///part_11.stl"/>
</geometry>
<material name="part_11_material">
<color rgba="0.49803921568627451677 0.49803921568627451677 0.49803921568627451677 1.0"/>
</material>
</visual>
<collision>
<origin xyz="-0.30299741173028005292 -0.010002240538597134689 -0.24499999999999966249" rpy="1.57079632679489678 1.1425778869832579519e-15 -1.1280364284126089603e-16" />
<geometry>
<mesh filename="package:///part_11.stl"/>
</geometry>
</collision>
<visual>
<origin xyz="-0.13214254961996313442 -0.010002240538597120811 -0.044999999999999956701" rpy="1.570796326794896558 1.0245381693342781752e-16 -2.5895484229582495027e-18" />
<geometry>
<mesh filename="package:///part_6.stl"/>
</geometry>
<material name="part_6_material">
<color rgba="0.91764705882352937127 0.91764705882352937127 0.91764705882352937127 1.0"/>
</material>
</visual>
<collision>
<origin xyz="-0.13214254961996313442 -0.010002240538597120811 -0.044999999999999956701" rpy="1.570796326794896558 1.0245381693342781752e-16 -2.5895484229582495027e-18" />
<geometry>
<mesh filename="package:///part_6.stl"/>
</geometry>
</collision>
<visual>
<origin xyz="-0.30390026077865572862 -0.010002240538597176323 0.15350000000000035838" rpy="1.570796326794896558 1.1447887593478441904e-15 6.6294260588480914976e-17" />
<geometry>
<mesh filename="package:///mg995_v3.stl"/>
</geometry>
<material name="mg995_v3_material">
<color rgba="0.62745098039215685404 0.62745098039215685404 0.62745098039215685404 1.0"/>
</material>
</visual>
<collision>
<origin xyz="-0.30390026077865572862 -0.010002240538597176323 0.15350000000000035838" rpy="1.570796326794896558 1.1447887593478441904e-15 6.6294260588480914976e-17" />
<geometry>
<mesh filename="package:///mg995_v3.stl"/>
</geometry>
</collision>
<inertial>
<origin xyz="-0.063706673597089494288 -3.8498478454393727098e-06 -0.025894328139315459653" rpy="0 0 0"/>
<mass value="0.084196217898659775347" />
<inertia ixx="2.7955415541966270181e-05" ixy="-1.3492807390254740625e-08"  ixz="-6.008302955970581974e-07" iyy="0.00010348466964737600311" iyz="-2.2291674578628228843e-09" izz="9.2987564203425755608e-05" />
</inertial>
</link>

<link name="gg_leg_middle_12">
<visual>
<origin xyz="-0.30299741173028849062 -0.010002240538597079178 -0.24500000000000571321" rpy="1.57079632679489678 -7.6062380818059420987e-17 -8.306805956312528437e-18" />
<geometry>
<mesh filename="package:///part_11.stl"/>
</geometry>
<material name="part_11_material">
<color rgba="0.49803921568627451677 0.49803921568627451677 0.49803921568627451677 1.0"/>
</material>
</visual>
<collision>
<origin xyz="-0.30299741173028849062 -0.010002240538597079178 -0.24500000000000571321" rpy="1.57079632679489678 -7.6062380818059420987e-17 -8.306805956312528437e-18" />
<geometry>
<mesh filename="package:///part_11.stl"/>
</geometry>
</collision>
<visual>
<origin xyz="-0.13214254961996313442 -0.010002240538597093056 -0.045000000000000019151" rpy="1.570796326794896558 -7.5722246608123243484e-17 1.9289959591227100185e-17" />
<geometry>
<mesh filename="package:///part_6.stl"/>
</geometry>
<material name="part_6_material">
<color rgba="0.91764705882352937127 0.91764705882352937127 0.91764705882352937127 1.0"/>
</material>
</visual>
<collision>
<origin xyz="-0.13214254961996313442 -0.010002240538597093056 -0.045000000000000019151" rpy="1.570796326794896558 -7.5722246608123243484e-17 1.9289959591227100185e-17" />
<geometry>
<mesh filename="package:///part_6.stl"/>
</geometry>
</collision>
<visual>
<origin xyz="-0.30390026077866050258 -0.010002240538597495512 0.15350000000000960099" rpy="1.57079632679489678 -7.521204529321897723e-17 6.0685107912536547741e-17" />
<geometry>
<mesh filename="package:///mg995_v3.stl"/>
</geometry>
<material name="mg995_v3_material">
<color rgba="0.62745098039215685404 0.62745098039215685404 0.62745098039215685404 1.0"/>
</material>
</visual>
<collision>
<origin xyz="-0.30390026077866050258 -0.010002240538597495512 0.15350000000000960099" rpy="1.57079632679489678 -7.521204529321897723e-17 6.0685107912536547741e-17" />
<geometry>
<mesh filename="package:///mg995_v3.stl"/>
</geometry>
</collision>
<inertial>
<origin xyz="-0.063706673597094462536 -3.8498478455567587708e-06 -0.02589432813931296512" rpy="0 0 0"/>
<mass value="0.084196217898659775347" />
<inertia ixx="2.7955415541965866993e-05" ixy="-1.3492807390558522705e-08"  ixz="-6.0083029558803422601e-07" iyy="0.00010348466964738310464" iyz="-2.2291674578689572558e-09" izz="9.2987564203433236603e-05" />
</inertial>
</link>

<link name="gg_leg_tip_6">
<visual>
<origin xyz="-0.13214254961996318993 -0.010002240538597106934 -0.044999999999999984457" rpy="1.570796326794896558 -1.2261285071288114317e-17 -1.0485614699912491705e-17" />
<geometry>
<mesh filename="package:///part_6.stl"/>
</geometry>
<material name="part_6_material">
<color rgba="0.91764705882352937127 0.91764705882352937127 0.91764705882352937127 1.0"/>
</material>
</visual>
<collision>
<origin xyz="-0.13214254961996318993 -0.010002240538597106934 -0.044999999999999984457" rpy="1.570796326794896558 -1.2261285071288114317e-17 -1.0485614699912491705e-17" />
<geometry>
<mesh filename="package:///part_6.stl"/>
</geometry>
</collision>
<visual>
<origin xyz="-0.12259449000000011143 0.0098031712025949124811 -0.025281761415826484174" rpy="-1.5707963267948861219 1.5707963267948961139 0" />
<geometry>
<mesh filename="package:///led_3mm_trans.stl"/>
</geometry>
<material name="led_3mm_trans_material">
<color rgba="1 1 1 1.0"/>
</material>
</visual>
<collision>
<origin xyz="-0.12259449000000011143 0.0098031712025949124811 -0.025281761415826484174" rpy="-1.5707963267948861219 1.5707963267948961139 0" />
<geometry>
<mesh filename="package:///led_3mm_trans.stl"/>
</geometry>
</collision>
<visual>
<origin xyz="-0.12029449000000008718 0.010865472711805337913 -0.024348211468834229931" rpy="3.1415926535897904515 4.6055026245337971223e-16 -1.5707963267949043296" />
<geometry>
<mesh filename="package:///pulsador.stl"/>
</geometry>
<material name="pulsador_material">
<color rgba="1 0 0 1.0"/>
</material>
</visual>
<collision>
<origin xyz="-0.12029449000000008718 0.010865472711805337913 -0.024348211468834229931" rpy="3.1415926535897904515 4.6055026245337971223e-16 -1.5707963267949043296" />
<geometry>
<mesh filename="package:///pulsador.stl"/>
</geometry>
</collision>
<visual>
<origin xyz="-0.026494490000000037178 0.14717946631849010419 -0.050978735407716774253" rpy="3.1415926535897922278 -8.8843484732241657542e-17 1.570796326794896558" />
<geometry>
<mesh filename="package:///part_25.stl"/>
</geometry>
<material name="part_25_material">
<color rgba="0.30196078431372547213 0.29019607843137257275 0.26274509803921569651 1.0"/>
</material>
</visual>
<collision>
<origin xyz="-0.026494490000000037178 0.14717946631849010419 -0.050978735407716774253" rpy="3.1415926535897922278 -8.8843484732241657542e-17 1.570796326794896558" />
<geometry>
<mesh filename="package:///part_25.stl"/>
</geometry>
</collision>
<inertial>
<origin xyz="-0.058600447713097768287 0.00030798747790674571622 -0.025499135322571492984" rpy="0 0 0"/>
<mass value="0.15555503524263536441" />
<inertia ixx="4.2100962384746066299e-05" ixy="5.2877209940367459067e-06"  ixz="2.0615243018214935649e-07" iyy="0.00015940278081236447473" iyz="2.8650165663781043229e-08" izz="0.00015063387305898009744" />
</inertial>
</link>

<joint name="lf4" type="revolute">
<origin xyz="-0.093900260629668164114 -2.2405385993323756466e-06 -1.5959455978986625269e-15" rpy="2.5763786282977065192e-15 2.4104969378378456387e-14 -0.012112832002087479955" />
<parent link="gg_leg_middle_12" />
<child link="gg_leg_tip_6" />
<axis xyz="0 0 1"/>
<limit effort="1" velocity="20" />
<joint_properties friction="0.0"/>
</joint>

<joint name="lf3" type="revolute">
<origin xyz="-0.093900260629688148128 -2.2405385992629867076e-06 -2.3314683517128287349e-15" rpy="-4.4476659239129598236e-15 -1.5022594948405059049e-14 0.0137910727754082061" />
<parent link="gg_leg_middle_11" />
<child link="gg_leg_middle_12" />
<axis xyz="0 0 1"/>
<limit effort="1" velocity="20" />
<joint_properties friction="0.0"/>
</joint>

<joint name="lf2" type="revolute">
<origin xyz="-0.093900260629652412825 0.025499999999999946321 -0.025497759461402286219" rpy="-1.5707963267948972241 -0.049281593424652790636 8.8578587657112694897e-15" />
<parent link="gg_leg_base_6" />
<child link="gg_leg_middle_11" />
<axis xyz="0 0 1"/>
<limit effort="1" velocity="20" />
<joint_properties friction="0.0"/>
</joint>

<joint name="lf1" type="revolute">
<origin xyz="-0.072167298280697816937 -0.039822632500807531031 -0.088021391225128003954" rpy="0.01228573826395177801 -0.070828108474379994353 0.95555005564723927147" />
<parent link="gg_head" />
<child link="gg_leg_base_6" />
<axis xyz="0 0 1"/>
<limit effort="1" velocity="20" />
<joint_properties friction="0.0"/>
</joint>


</robot>
